Workbook

Sheet אפריל 24
A1: תאריך | B1: יום | C1: פניות כתובות נפתחו | D1: שיחות נכנסות | E1: הערות | F1: מספר נציגים | G1: שיחות ללא כפילויות | H1: פיק
A2: =DATE(2024,4,1) + ROW(A1) - 1 -> 45383 | B2: =TEXT(A2,"dddd") -> יום שני | C2: 333 | D2: 629 | E2: נוכחות | F2: 16 | G2: 496 | H2: 1
A3: =DATE(2024,4,1) + ROW(A2) - 1 -> 45384 | B3: =TEXT(A3,"dddd") -> יום שלישי | C3: 236 | D3: 294 | F3: 14 | G3: 263 | H3: 0
A4: =DATE(2024,4,1) + ROW(A3) - 1 -> 45385 | B4: =TEXT(A4,"dddd") -> יום רביעי | C4: 187 | D4: 247 | F4: 15 | G4: 210 | H4: 0
A5: =DATE(2024,4,1) + ROW(A4) - 1 -> 45386 | B5: =TEXT(A5,"dddd") -> יום חמישי | C5: 168 | D5: 227 | F5: 11 | G5: 192 | H5: 0
A6: =DATE(2024,4,1) + ROW(A5) - 1 -> 45387 | B6: =TEXT(A6,"dddd") -> יום שישי | C6: 22 | D6: 0 | E6: חופש | H6: 0
A7: =DATE(2024,4,1) + ROW(A6) - 1 -> 45388 | B7: =TEXT(A7,"dddd") -> שבת | C7: 6 | D7: 0 | E7: חופש | H7: 0
A8: =DATE(2024,4,1) + ROW(A7) - 1 -> 45389 | B8: =TEXT(A8,"dddd") -> יום ראשון | C8: 391 | D8: 496 | E8: שכר | F8: 16 | G8: 435 | H8: 1
A9: =DATE(2024,4,1) + ROW(A8) - 1 -> 45390 | B9: =TEXT(A9,"dddd") -> יום שני | C9: 405 | D9: 500 | E9: שכר | F9: 16 | G9: 426 | H9: 1
A10: =DATE(2024,4,1) + ROW(A9) - 1 -> 45391 | B10: =TEXT(A10,"dddd") -> יום שלישי | C10: 314 | D10: 370 | E10: שכר | F10: 17 | G10: 317 | H10: 1
A11: =DATE(2024,4,1) + ROW(A10) - 1 -> 45392 | B11: =TEXT(A11,"dddd") -> יום רביעי | C11: 299 | D11: 360 | E11: שכר | F11: 15 | G11: 319 | H11: 1
A12: =DATE(2024,4,1) + ROW(A11) - 1 -> 45393 | B12: =TEXT(A12,"dddd") -> יום חמישי | C12: 267 | D12: 339 | E12: שכר | F12: 14 | G12: 297 | H12: 1
A13: =DATE(2024,4,1) + ROW(A12) - 1 -> 45394 | B13: =TEXT(A13,"dddd") -> יום שישי | C13: 33 | D13: 0 | E13: חופש | H13: 0
A14: =DATE(2024,4,1) + ROW(A13) - 1 -> 45395 | B14: =TEXT(A14,"dddd") -> שבת | C14: 6 | D14: 0 | E14: חופש | H14: 0
A15: =DATE(2024,4,1) + ROW(A14) - 1 -> 45396 | B15: =TEXT(A15,"dddd") -> יום ראשון | C15: 300 | D15: 304 | F15: 8 | G15: 257 | H15: 0
A16: =DATE(2024,4,1) + ROW(A15) - 1 -> 45397 | B16: =TEXT(A16,"dddd") -> יום שני | C16: 351 | D16: 375 | F16: 12 | G16: 322 | H16: 0
A17: =DATE(2024,4,1) + ROW(A16) - 1 -> 45398 | B17: =TEXT(A17,"dddd") -> יום שלישי | C17: 445 | D17: 421 | F17: 14 | G17: 353 | H17: 0
A18: =DATE(2024,4,1) + ROW(A17) - 1 -> 45399 | B18: =TEXT(A18,"dddd") -> יום רביעי | C18: 364 | D18: 386 | F18: 14 | G18: 336 | H18: 0
A19: =DATE(2024,4,1) + ROW(A18) - 1 -> 45400 | B19: =TEXT(A19,"dddd") -> יום חמישי | C19: 344 | D19: 414 | F19: 15 | G19: 348 | H19: 0
A20: =DATE(2024,4,1) + ROW(A19) - 1 -> 45401 | B20: =TEXT(A20,"dddd") -> יום שישי | C20: 23 | D20: 0 | E20: חופש | F20: 0 | H20: 0
A21: =DATE(2024,4,1) + ROW(A20) - 1 -> 45402 | B21: =TEXT(A21,"dddd") -> שבת | C21: 7 | D21: 0 | E21: חופש | F21: 0 | H21: 0
A22: =DATE(2024,4,1) + ROW(A21) - 1 -> 45403 | B22: =TEXT(A22,"dddd") -> יום ראשון | C22: 388 | D22: 429 | F22: 12 | G22: 352 | H22: 0
A23: =DATE(2024,4,1) + ROW(A22) - 1 -> 45404 | B23: =TEXT(A23,"dddd") -> יום שני | C23: 16 | D23: 0 | E23: חופש | F23: 0 | G23: 0 | H23: 0
A24: =DATE(2024,4,1) + ROW(A23) - 1 -> 45405 | B24: =TEXT(A24,"dddd") -> יום שלישי | C24: 4 | D24: 0 | E24: חופש | F24: 0 | G24: 0 | H24: 0
A25: =DATE(2024,4,1) + ROW(A24) - 1 -> 45406 | B25: =TEXT(A25,"dddd") -> יום רביעי | C25: 50 | D25: 0 | E25: חופש | F25: 0 | G25: 0 | H25: 0
A26: =DATE(2024,4,1) + ROW(A25) - 1 -> 45407 | B26: =TEXT(A26,"dddd") -> יום חמישי | C26: 81 | D26: 1 | E26: חופש | F26: 0 | G26: 0 | H26: 0
A27: =DATE(2024,4,1) + ROW(A26) - 1 -> 45408 | B27: =TEXT(A27,"dddd") -> יום שישי | C27: 15 | D27: 0 | E27: חופש | F27: 0 | G27: 0 | H27: 0
A28: =DATE(2024,4,1) + ROW(A27) - 1 -> 45409 | B28: =TEXT(A28,"dddd") -> שבת | C28: 6 | D28: 0 | E28: חופש | F28: 0 | G28: 0 | H28: 0
A29: =DATE(2024,4,1) + ROW(A28) - 1 -> 45410 | B29: =TEXT(A29,"dddd") -> יום ראשון | C29: 14 | D29: 0 | E29: חופש | F29: 0 | G29: 0 | H29: 0
A30: =DATE(2024,4,1) + ROW(A29) - 1 -> 45411 | B30: =TEXT(A30,"dddd") -> יום שני | C30: 11 | D30: 0 | E30: חופש | F30: 0 | G30: 0 | H30: 0
A31: =DATE(2024,4,1) + ROW(A30) - 1 -> 45412 | B31: =TEXT(A31,"dddd") -> יום שלישי | C31: 709 | D31: 1170 | E31: נוכחות | F31: 18 | G31: 912 | H31: 1

Sheet מאי 24
A1: תאריך | B1: יום | C1: פניות כתובות נפתחו | D1: שיחות נכנסות | E1: הערות | F1: מספר נציגים | G1: שיחות ללא כפילויות | H1: פיק
A2: =DATE(2024,5,1) + ROW(A1) - 1 -> 45413 | B2: =TEXT(A2,"dddd") -> יום רביעי | C2: 354 | D2: 1170 | E2: נוכחות | F2: 16 | G2: 617 | H2: 1
A3: =DATE(2024,5,1) + ROW(A2) - 1 -> 45414 | B3: =TEXT(A3,"dddd") -> יום חמישי | C3: 210 | D3: 298 | F3: 15 | G3: 263 | H3: 0
A4: =DATE(2024,5,1) + ROW(A3) - 1 -> 45415 | B4: =TEXT(A4,"dddd") -> יום שישי | C4: 21 | D4: 0 | E4: חופש | F4: 0 | H4: 0
A5: =DATE(2024,5,1) + ROW(A4) - 1 -> 45416 | B5: =TEXT(A5,"dddd") -> שבת | C5: 7 | D5: 0 | E5: חופש | F5: 0 | H5: 0
A6: =DATE(2024,5,1) + ROW(A5) - 1 -> 45417 | B6: =TEXT(A6,"dddd") -> יום ראשון | C6: 298 | D6: 304 | F6: 11 | G6: 269 | H6: 0
A7: =DATE(2024,5,1) + ROW(A6) - 1 -> 45418 | B7: =TEXT(A7,"dddd") -> יום שני | C7: 253 | D7: 197 | F7: 15 | G7: 178 | H7: 0
A8: =DATE(2024,5,1) + ROW(A7) - 1 -> 45419 | B8: =TEXT(A8,"dddd") -> יום שלישי | C8: 368 | D8: 617 | E8: שכר | F8: 17 | G8: 519 | H8: 1
A9: =DATE(2024,5,1) + ROW(A8) - 1 -> 45420 | B9: =TEXT(A9,"dddd") -> יום רביעי | C9: 230 | D9: 374 | E9: שכר | F9: 15 | G9: 335 | H9: 1
A10: =DATE(2024,5,1) + ROW(A9) - 1 -> 45421 | B10: =TEXT(A10,"dddd") -> יום חמישי | C10: 251 | D10: 386 | E10: שכר | F10: 14 | G10: 329 | H10: 1
A11: =DATE(2024,5,1) + ROW(A10) - 1 -> 45422 | B11: =TEXT(A11,"dddd") -> יום שישי | C11: 31 | D11: 0 | E11: חופש | F11: 0 | H11: 0
A12: =DATE(2024,5,1) + ROW(A11) - 1 -> 45423 | B12: =TEXT(A12,"dddd") -> שבת | C12: 4 | D12: 0 | E12: חופש | F12: 0 | H12: 0
A13: =DATE(2024,5,1) + ROW(A12) - 1 -> 45424 | B13: =TEXT(A13,"dddd") -> יום ראשון | C13: 334 | D13: 369 | E13: שכר | F13: 14 | G13: 327 | H13: 1
A14: =DATE(2024,5,1) + ROW(A13) - 1 -> 45425 | B14: =TEXT(A14,"dddd") -> יום שני | C14: 34 | D14: 0 | E14: חופש | F14: 0 | H14: 0
A15: =DATE(2024,5,1) + ROW(A14) - 1 -> 45426 | B15: =TEXT(A15,"dddd") -> יום שלישי | C15: 7 | D15: 0 | E15: חופש | F15: 0 | H15: 0
A16: =DATE(2024,5,1) + ROW(A15) - 1 -> 45427 | B16: =TEXT(A16,"dddd") -> יום רביעי | C16: 387 | D16: 336 | F16: 14 | G16: 296 | H16: 0
A17: =DATE(2024,5,1) + ROW(A16) - 1 -> 45428 | B17: =TEXT(A17,"dddd") -> יום חמישי | C17: 276 | D17: 309 | F17: 11 | G17: 281 | H17: 0
A18: =DATE(2024,5,1) + ROW(A17) - 1 -> 45429 | B18: =TEXT(A18,"dddd") -> יום שישי | C18: 21 | D18: 0 | E18: חופש | F18: 0 | H18: 0
A19: =DATE(2024,5,1) + ROW(A18) - 1 -> 45430 | B19: =TEXT(A19,"dddd") -> שבת | C19: 5 | D19: 0 | E19: חופש | F19: 0 | H19: 0
A20: =DATE(2024,5,1) + ROW(A19) - 1 -> 45431 | B20: =TEXT(A20,"dddd") -> יום ראשון | C20: 380 | D20: 359 | F20: 13 | G20: 311 | H20: 0
A21: =DATE(2024,5,1) + ROW(A20) - 1 -> 45432 | B21: =TEXT(A21,"dddd") -> יום שני | C21: 350 | D21: 369 | F21: 15 | G21: 314 | H21: 0
A22: =DATE(2024,5,1) + ROW(A21) - 1 -> 45433 | B22: =TEXT(A22,"dddd") -> יום שלישי | C22: 403 | D22: 344 | F22: 13 | G22: 304 | H22: 0
A23: =DATE(2024,5,1) + ROW(A22) - 1 -> 45434 | B23: =TEXT(A23,"dddd") -> יום רביעי | C23: 369 | D23: 335 | F23: 13 | G23: 290 | H23: 0
A24: =DATE(2024,5,1) + ROW(A23) - 1 -> 45435 | B24: =TEXT(A24,"dddd") -> יום חמישי | C24: 275 | D24: 378 | F24: 13 | G24: 334 | H24: 0
A25: =DATE(2024,5,1) + ROW(A24) - 1 -> 45436 | B25: =TEXT(A25,"dddd") -> יום שישי | C25: 33 | D25: 0 | E25: חופש | F25: 0 | H25: 0
A26: =DATE(2024,5,1) + ROW(A25) - 1 -> 45437 | B26: =TEXT(A26,"dddd") -> שבת | C26: 12 | D26: 0 | E26: חופש | F26: 0 | H26: 0
A27: =DATE(2024,5,1) + ROW(A26) - 1 -> 45438 | B27: =TEXT(A27,"dddd") -> יום ראשון | C27: 448 | D27: 520 | F27: 15 | G27: 459 | H27: 0
A28: =DATE(2024,5,1) + ROW(A27) - 1 -> 45439 | B28: =TEXT(A28,"dddd") -> יום שני | C28: 389 | D28: 452 | F28: 15 | G28: 392 | H28: 0
A29: =DATE(2024,5,1) + ROW(A28) - 1 -> 45440 | B29: =TEXT(A29,"dddd") -> יום שלישי | C29: 309 | D29: 499 | E29: נוכחות | F29: 16 | G29: 401 | H29: 1
A30: =DATE(2024,5,1) + ROW(A29) - 1 -> 45441 | B30: =TEXT(A30,"dddd") -> יום רביעי | C30: 305 | D30: 463 | E30: נוכחות | F30: 16 | G30: 386 | H30: 1
A31: =DATE(2024,5,1) + ROW(A30) - 1 -> 45442 | B31: =TEXT(A31,"dddd") -> יום חמישי | C31: 313 | D31: 610 | E31: נוכחות | F31: 16 | G31: 494 | H31: 1
A32: =DATE(2024,5,1) + ROW(A31) - 1 -> 45443 | B32: =TEXT(A32,"dddd") -> יום שישי | C32: 24 | D32: 0 | E32: חופש | F32: 0 | H32: 0

Sheet יוני 24
A1: תאריך | B1: יום | C1: פניות כתובות נפתחו | D1: שיחות נכנסות | E1: הערות | F1: מספר נציגים | G1: שיחות ללא כפילויות | H1: פיק
A2: =DATE(2024,6,1) + ROW(A1) - 1 -> 45444 | B2: =TEXT(A2,"dddd") -> שבת | C2: 11 | D2: 0 | E2: חופש | H2: 0
A3: =DATE(2024,6,1) + ROW(A2) - 1 -> 45445 | B3: =TEXT(A3,"dddd") -> יום ראשון | C3: 312 | D3: 561 | F3: 18 | G3: 477 | H3: 0
A4: =DATE(2024,6,1) + ROW(A3) - 1 -> 45446 | B4: =TEXT(A4,"dddd") -> יום שני | C4: 209 | D4: 259 | F4: 12 | G4: 231 | H4: 0
A5: =DATE(2024,6,1) + ROW(A4) - 1 -> 45447 | B5: =TEXT(A5,"dddd") -> יום שלישי | C5: 170 | D5: 216 | F5: 13 | G5: 195 | H5: 0
A6: =DATE(2024,6,1) + ROW(A5) - 1 -> 45448 | B6: =TEXT(A6,"dddd") -> יום רביעי | C6: 174 | D6: 178 | F6: 17 | G6: 160 | H6: 0
A7: =DATE(2024,6,1) + ROW(A6) - 1 -> 45449 | B7: =TEXT(A7,"dddd") -> יום חמישי | C7: 243 | D7: 389 | F7: 17 | G7: 336 | H7: 0
A8: =DATE(2024,6,1) + ROW(A7) - 1 -> 45450 | B8: =TEXT(A8,"dddd") -> יום שישי | C8: 27 | D8: 0 | E8: חופש | F8: 0 | H8: 0
A9: =DATE(2024,6,1) + ROW(A8) - 1 -> 45451 | B9: =TEXT(A9,"dddd") -> שבת | C9: 7 | D9: 0 | E9: חופש | F9: 0 | H9: 0
A10: =DATE(2024,6,1) + ROW(A9) - 1 -> 45452 | B10: =TEXT(A10,"dddd") -> יום ראשון | C10: 324 | D10: 388 | E10: שכר | F10: 17 | G10: 339 | H10: 1
A11: =DATE(2024,6,1) + ROW(A10) - 1 -> 45453 | B11: =TEXT(A11,"dddd") -> יום שני | C11: 364 | D11: 315 | E11: שכר | F11: 17 | G11: 272 | H11: 1
A12: =DATE(2024,6,1) + ROW(A11) - 1 -> 45454 | B12: =TEXT(A12,"dddd") -> יום שלישי | C12: 35 | D12: 0 | E12: חופש | F12: 0 | H12: 0
A13: =DATE(2024,6,1) + ROW(A12) - 1 -> 45455 | B13: =TEXT(A13,"dddd") -> יום רביעי | C13: 16 | D13: 0 | E13: חופש | F13: 0 | H13: 0
A14: =DATE(2024,6,1) + ROW(A13) - 1 -> 45456 | B14: =TEXT(A14,"dddd") -> יום חמישי | C14: 354 | D14: 358 | E14: שכר | F14: 14 | G14: 312 | H14: 1
A15: =DATE(2024,6,1) + ROW(A14) - 1 -> 45457 | B15: =TEXT(A15,"dddd") -> יום שישי | C15: 26 | D15: 0 | E15: חופש | F15: 0 | H15: 0
A16: =DATE(2024,6,1) + ROW(A15) - 1 -> 45458 | B16: =TEXT(A16,"dddd") -> שבת | C16: 12 | D16: 0 | E16: חופש | F16: 0 | H16: 0
A17: =DATE(2024,6,1) + ROW(A16) - 1 -> 45459 | B17: =TEXT(A17,"dddd") -> יום ראשון | C17: 551 | D17: 406 | F17: 16 | G17: 354 | H17: 0
A18: =DATE(2024,6,1) + ROW(A17) - 1 -> 45460 | B18: =TEXT(A18,"dddd") -> יום שני | C18: 458 | D18: 367 | F18: 16 | G18: 306 | H18: 0
A19: =DATE(2024,6,1) + ROW(A18) - 1 -> 45461 | B19: =TEXT(A19,"dddd") -> יום שלישי | C19: 338 | D19: 400 | F19: 17 | G19: 342 | H19: 0
A20: =DATE(2024,6,1) + ROW(A19) - 1 -> 45462 | B20: =TEXT(A20,"dddd") -> יום רביעי | C20: 285 | D20: 280 | F20: 17 | G20: 254 | H20: 0
A21: =DATE(2024,6,1) + ROW(A20) - 1 -> 45463 | B21: =TEXT(A21,"dddd") -> יום חמישי | C21: 246 | D21: 263 | F21: 16 | G21: 231 | H21: 0
A22: =DATE(2024,6,1) + ROW(A21) - 1 -> 45464 | B22: =TEXT(A22,"dddd") -> יום שישי | C22: 26 | D22: 0 | E22: חופש | F22: 0 | H22: 0
A23: =DATE(2024,6,1) + ROW(A22) - 1 -> 45465 | B23: =TEXT(A23,"dddd") -> שבת | C23: 3 | D23: 0 | E23: חופש | F23: 0 | H23: 0
A24: =DATE(2024,6,1) + ROW(A23) - 1 -> 45466 | B24: =TEXT(A24,"dddd") -> יום ראשון | C24: 390 | D24: 351 | F24: 16 | G24: 292 | H24: 0
A25: =DATE(2024,6,1) + ROW(A24) - 1 -> 45467 | B25: =TEXT(A25,"dddd") -> יום שני | C25: 340 | D25: 304 | F25: 16 | G25: 269 | H25: 0
A26: =DATE(2024,6,1) + ROW(A25) - 1 -> 45468 | B26: =TEXT(A26,"dddd") -> יום שלישי | C26: 351 | D26: 393 | F26: 16 | G26: 336 | H26: 0
A27: =DATE(2024,6,1) + ROW(A26) - 1 -> 45469 | B27: =TEXT(A27,"dddd") -> יום רביעי | C27: 332 | D27: 487 | F27: 18 | G27: 400 | H27: 0
A28: =DATE(2024,6,1) + ROW(A27) - 1 -> 45470 | B28: =TEXT(A28,"dddd") -> יום חמישי | C28: 346 | D28: 439 | F28: 17 | G28: 363 | H28: 0
A29: =DATE(2024,6,1) + ROW(A28) - 1 -> 45471 | B29: =TEXT(A29,"dddd") -> יום שישי | C29: 27 | D29: 0 | E29: חופש | F29: 0 | H29: 0
A30: =DATE(2024,6,1) + ROW(A29) - 1 -> 45472 | B30: =TEXT(A30,"dddd") -> שבת | C30: 12 | D30: 0 | E30: חופש | F30: 0 | H30: 0
A31: =DATE(2024,6,1) + ROW(A30) - 1 -> 45473 | B31: =TEXT(A31,"dddd") -> יום ראשון | C31: 433 | D31: 608 | E31: נוכחות | F31: 14 | G31: 497 | H31: 1

Sheet ינואר 25
A1: תאריך | B1: יום | C1: פניות כתובות נפתחו | D1: שיחות נכנסות | E1: הערות | F1: מספר נציגים | G1: שיחות ללא כפילויות | H1: פיק
A2: =DATE(2025,1,1) + ROW(A1) - 1 -> 45658 | B2: =TEXT(A2,"dddd") -> יום רביעי | C2: 439 | D2: 769 | F2: 15 | G2: 556 | H2: 0
A3: =DATE(2025,1,1) + ROW(A2) - 1 -> 45659 | B3: =TEXT(A3,"dddd") -> יום חמישי | C3: 328 | D3: 370 | F3: 13 | G3: 317 | H3: 0
A4: =DATE(2025,1,1) + ROW(A3) - 1 -> 45660 | B4: =TEXT(A4,"dddd") -> יום שישי | C4: 0 | D4: 0 | E4: חופש | F4: 0 | H4: 0
A5: =DATE(2025,1,1) + ROW(A4) - 1 -> 45661 | B5: =TEXT(A5,"dddd") -> שבת | C5: 0 | D5: 0 | E5: חופש | F5: 0 | H5: 0
A6: =DATE(2025,1,1) + ROW(A5) - 1 -> 45662 | B6: =TEXT(A6,"dddd") -> יום ראשון | C6: 350 | D6: 367 | F6: 14 | G6: 327 | H6: 0
A7: =DATE(2025,1,1) + ROW(A6) - 1 -> 45663 | B7: =TEXT(A7,"dddd") -> יום שני | C7: 324 | D7: 304 | F7: 14 | H7: 0
A8: =DATE(2025,1,1) + ROW(A7) - 1 -> 45664 | B8: =TEXT(A8,"dddd") -> יום שלישי | C8: 430 | D8: 768 | E8: שכר | F8: 17 | G8: 620 | H8: 1
A9: =DATE(2025,1,1) + ROW(A8) - 1 -> 45665 | B9: =TEXT(A9,"dddd") -> יום רביעי | C9: 430 | D9: 513 | E9: שכר | F9: 15 | G9: 433 | H9: 1
A10: =DATE(2025,1,1) + ROW(A9) - 1 -> 45666 | B10: =TEXT(A10,"dddd") -> יום חמישי | C10: 343 | D10: 427 | E10: שכר | F10: 15 | G10: 352 | H10: 1
A11: =DATE(2025,1,1) + ROW(A10) - 1 -> 45667 | B11: =TEXT(A11,"dddd") -> יום שישי | C11: 0 | D11: 0 | E11: חופש | F11: 0 | H11: 0
A12: =DATE(2025,1,1) + ROW(A11) - 1 -> 45668 | B12: =TEXT(A12,"dddd") -> שבת | C12: 0 | D12: 0 | E12: חופש | F12: 0 | H12: 0
A13: =DATE(2025,1,1) + ROW(A12) - 1 -> 45669 | B13: =TEXT(A13,"dddd") -> יום ראשון | C13: 596 | D13: 454 | E13: שכר | F13: 11 | G13: 391 | H13: 1
A14: =DATE(2025,1,1) + ROW(A13) - 1 -> 45670 | B14: =TEXT(A14,"dddd") -> יום שני | C14: 392 | D14: 381 | E14: שכר | F14: 11 | G14: 335 | H14: 1
A15: =DATE(2025,1,1) + ROW(A14) - 1 -> 45671 | B15: =TEXT(A15,"dddd") -> יום שלישי | C15: 384 | D15: 365 | F15: 14 | G15: 299 | H15: 0
A16: =DATE(2025,1,1) + ROW(A15) - 1 -> 45672 | B16: =TEXT(A16,"dddd") -> יום רביעי | C16: 286 | D16: 323 | F16: 15 | G16: 277 | H16: 0
A17: =DATE(2025,1,1) + ROW(A16) - 1 -> 45673 | B17: =TEXT(A17,"dddd") -> יום חמישי | C17: 309 | D17: 295 | F17: 16 | G17: 255 | H17: 0
A18: =DATE(2025,1,1) + ROW(A17) - 1 -> 45674 | B18: =TEXT(A18,"dddd") -> יום שישי | C18: 0 | D18: 0 | E18: חופש | F18: 0 | H18: 0
A19: =DATE(2025,1,1) + ROW(A18) - 1 -> 45675 | B19: =TEXT(A19,"dddd") -> שבת | C19: 0 | D19: 0 | E19: חופש | F19: 0 | H19: 0
A20: =DATE(2025,1,1) + ROW(A19) - 1 -> 45676 | B20: =TEXT(A20,"dddd") -> יום ראשון | C20: 491 | D20: 360 | F20: 15 | G20: 308 | H20: 0
A21: =DATE(2025,1,1) + ROW(A20) - 1 -> 45677 | B21: =TEXT(A21,"dddd") -> יום שני | C21: 314 | D21: 298 | F21: 11 | G21: 248 | H21: 0
A22: =DATE(2025,1,1) + ROW(A21) - 1 -> 45678 | B22: =TEXT(A22,"dddd") -> יום שלישי | C22: 401 | D22: 318 | F22: 13 | G22: 261 | H22: 0
A23: =DATE(2025,1,1) + ROW(A22) - 1 -> 45679 | B23: =TEXT(A23,"dddd") -> יום רביעי | C23: 291 | D23: 295 | F23: 9 | G23: 251 | H23: 0
A24: =DATE(2025,1,1) + ROW(A23) - 1 -> 45680 | B24: =TEXT(A24,"dddd") -> יום חמישי | C24: 378 | D24: 316 | F24: 12 | G24: 262 | H24: 0
A25: =DATE(2025,1,1) + ROW(A24) - 1 -> 45681 | B25: =TEXT(A25,"dddd") -> יום שישי | C25: 0 | D25: 0 | E25: חופש | F25: 0 | H25: 0
A26: =DATE(2025,1,1) + ROW(A25) - 1 -> 45682 | B26: =TEXT(A26,"dddd") -> שבת | C26: 0 | D26: 0 | E26: חופש | F26: 0 | H26: 0
A27: =DATE(2025,1,1) + ROW(A26) - 1 -> 45683 | B27: =TEXT(A27,"dddd") -> יום ראשון | C27: 382 | D27: 377 | F27: 13 | G27: 303 | H27: 0
A28: =DATE(2025,1,1) + ROW(A27) - 1 -> 45684 | B28: =TEXT(A28,"dddd") -> יום שני | C28: 337 | D28: 338 | F28: 14 | G28: 290 | H28: 0
A29: =DATE(2025,1,1) + ROW(A28) - 1 -> 45685 | B29: =TEXT(A29,"dddd") -> יום שלישי | C29: 375 | D29: 331 | E29: נוכחות | F29: 13 | G29: 274 | H29: 1
A30: =DATE(2025,1,1) + ROW(A29) - 1 -> 45686 | B30: =TEXT(A30,"dddd") -> יום רביעי | C30: 347 | D30: 351 | E30: נוכחות | F30: 16 | G30: 280 | H30: 1
A31: =DATE(2025,1,1) + ROW(A30) - 1 -> 45687 | B31: =TEXT(A31,"dddd") -> יום חמישי | C31: 345 | D31: 409 | E31: נוכחות | F31: 15 | G31: 327 | H31: 1
A32: =DATE(2025,1,1) + ROW(A31) - 1 -> 45688 | B32: =TEXT(A32,"dddd") -> יום שישי | C32: 0 | D32: 0 | E32: חופש | F32: 0 | H32: 0

Sheet פברואר 25
A1: תאריך | B1: יום | C1: פניות כתובות נפתחו | D1: שיחות נכנסות | E1: הערות | F1: מספר נציגים | G1: שיחות ללא כפילויות | H1: פיק
A2: =DATE(2025,2,1) + ROW(A1) - 1 -> 45689 | B2: =TEXT(A2,"dddd") -> שבת | C2: 0 | D2: 0 | E2: חופש | F2: 0 | H2: 0
A3: =DATE(2025,2,1) + ROW(A2) - 1 -> 45690 | B3: =TEXT(A3,"dddd") -> יום ראשון | C3: 355 | D3: 443 | F3: 13 | G3: 369 | H3: 0
A4: =DATE(2025,2,1) + ROW(A3) - 1 -> 45691 | B4: =TEXT(A4,"dddd") -> יום שני | C4: 262 | D4: 277 | F4: 13 | G4: 239 | H4: 0
A5: =DATE(2025,2,1) + ROW(A4) - 1 -> 45692 | B5: =TEXT(A5,"dddd") -> יום שלישי | C5: 253 | D5: 255 | F5: 12 | G5: 214 | H5: 0
A6: =DATE(2025,2,1) + ROW(A5) - 1 -> 45693 | B6: =TEXT(A6,"dddd") -> יום רביעי | C6: 252 | D6: 301 | F6: 13 | G6: 265 | H6: 0
A7: =DATE(2025,2,1) + ROW(A6) - 1 -> 45694 | B7: =TEXT(A7,"dddd") -> יום חמישי | C7: 413 | D7: 461 | F7: 13 | G7: 389 | H7: 0
A8: =DATE(2025,2,1) + ROW(A7) - 1 -> 45695 | B8: =TEXT(A8,"dddd") -> יום שישי | C8: 0 | D8: 0 | E8: חופש | F8: 0 | H8: 0
A9: =DATE(2025,2,1) + ROW(A8) - 1 -> 45696 | B9: =TEXT(A9,"dddd") -> שבת | C9: 0 | D9: 0 | E9: חופש | F9: 0 | H9: 0
A10: =DATE(2025,2,1) + ROW(A9) - 1 -> 45697 | B10: =TEXT(A10,"dddd") -> יום ראשון | C10: 515 | D10: 766 | E10: שכר | F10: 15 | G10: 600 | H10: 1
A11: =DATE(2025,2,1) + ROW(A10) - 1 -> 45698 | B11: =TEXT(A11,"dddd") -> יום שני | C11: 437 | D11: 468 | E11: שכר | F11: 13 | G11: 360 | H11: 1
A12: =DATE(2025,2,1) + ROW(A11) - 1 -> 45699 | B12: =TEXT(A12,"dddd") -> יום שלישי | C12: 399 | D12: 380 | E12: שכר | F12: 14 | G12: 326 | H12: 1
A13: =DATE(2025,2,1) + ROW(A12) - 1 -> 45700 | B13: =TEXT(A13,"dddd") -> יום רביעי | C13: 402 | D13: 476 | E13: שכר | F13: 13 | G13: 403 | H13: 1
A14: =DATE(2025,2,1) + ROW(A13) - 1 -> 45701 | B14: =TEXT(A14,"dddd") -> יום חמישי | C14: 359 | D14: 367 | E14: שכר | F14: 13 | G14: 299 | H14: 1
A15: =DATE(2025,2,1) + ROW(A14) - 1 -> 45702 | B15: =TEXT(A15,"dddd") -> יום שישי | C15: 0 | D15: 0 | E15: חופש | F15: 0 | H15: 0
A16: =DATE(2025,2,1) + ROW(A15) - 1 -> 45703 | B16: =TEXT(A16,"dddd") -> שבת | C16: 0 | D16: 0 | E16: חופש | F16: 0 | H16: 0
A17: =DATE(2025,2,1) + ROW(A16) - 1 -> 45704 | B17: =TEXT(A17,"dddd") -> יום ראשון | C17: 0 | D17: 0 | E17: חופש | F17: 0 | H17: 0
A18: =DATE(2025,2,1) + ROW(A17) - 1 -> 45705 | B18: =TEXT(A18,"dddd") -> יום שני | C18: 712 | D18: 482 | F18: 13 | G18: 393 | H18: 0
A19: =DATE(2025,2,1) + ROW(A18) - 1 -> 45706 | B19: =TEXT(A19,"dddd") -> יום שלישי | C19: 441 | D19: 377 | F19: 13 | G19: 324 | H19: 0
A20: =DATE(2025,2,1) + ROW(A19) - 1 -> 45707 | B20: =TEXT(A20,"dddd") -> יום רביעי | C20: 406 | D20: 353 | F20: 13 | G20: 298 | H20: 0
A21: =DATE(2025,2,1) + ROW(A20) - 1 -> 45708 | B21: =TEXT(A21,"dddd") -> יום חמישי | C21: 472 | D21: 627 | F21: 14 | G21: 533 | H21: 0
A22: =DATE(2025,2,1) + ROW(A21) - 1 -> 45709 | B22: =TEXT(A22,"dddd") -> יום שישי | C22: 0 | D22: 0 | E22: חופש | F22: 0 | H22: 0
A23: =DATE(2025,2,1) + ROW(A22) - 1 -> 45710 | B23: =TEXT(A23,"dddd") -> שבת | C23: 0 | D23: 0 | E23: חופש | F23: 0 | H23: 0
A24: =DATE(2025,2,1) + ROW(A23) - 1 -> 45711 | B24: =TEXT(A24,"dddd") -> יום ראשון | C24: 663 | D24: 1203 | E24: נוכחות | F24: 12 | G24: 879 | H24: 1
A25: =DATE(2025,2,1) + ROW(A24) - 1 -> 45712 | B25: =TEXT(A25,"dddd") -> יום שני | C25: 394 | D25: 690 | E25: נוכחות | F25: 14 | G25: 533 | H25: 1
A26: =DATE(2025,2,1) + ROW(A25) - 1 -> 45713 | B26: =TEXT(A26,"dddd") -> יום שלישי | C26: 347 | D26: 512 | E26: נוכחות | F26: 11 | G26: 418 | H26: 1
A27: =DATE(2025,2,1) + ROW(A26) - 1 -> 45714 | B27: =TEXT(A27,"dddd") -> יום רביעי | C27: 416 | D27: 457 | E27: נוכחות | F27: 13 | G27: 382 | H27: 1
A28: =DATE(2025,2,1) + ROW(A27) - 1 -> 45715 | B28: =TEXT(A28,"dddd") -> יום חמישי | C28: 462 | D28: 596 | E28: נוכחות | F28: 15 | G28: 497 | H28: 1
A29: =DATE(2025,2,1) + ROW(A28) - 1 -> 45716 | B29: =TEXT(A29,"dddd") -> יום שישי | C29: 0 | D29: 0 | E29: חופש | F29: 0 | H29: 0

Sheet מרץ 25
A1: תאריך | B1: יום | C1: פניות כתובות נפתחו | D1: שיחות נכנסות | E1: הערות | F1: מספר נציגים | G1: שיחות ללא כפילויות | H1: פיק
A2: =DATE(2025,3,1) + ROW(A1) - 1 -> 45717 | B2: =TEXT(A2,"dddd") -> שבת | C2: 0 | D2: 0 | E2: חופש | F2: 0 | H2: 0
A3: =DATE(2025,3,1) + ROW(A2) - 1 -> 45718 | B3: =TEXT(A3,"dddd") -> יום ראשון | C3: 428 | D3: 728 | F3: 11 | G3: 508 | H3: 0
A4: =DATE(2025,3,1) + ROW(A3) - 1 -> 45719 | B4: =TEXT(A4,"dddd") -> יום שני | C4: 254 | D4: 337 | F4: 11 | G4: 287 | H4: 0
A5: =DATE(2025,3,1) + ROW(A4) - 1 -> 45720 | B5: =TEXT(A5,"dddd") -> יום שלישי | C5: 267 | D5: 320 | F5: 11 | G5: 276 | H5: 0
A6: =DATE(2025,3,1) + ROW(A5) - 1 -> 45721 | B6: =TEXT(A6,"dddd") -> יום רביעי | C6: 236 | D6: 300 | F6: 11 | G6: 249 | H6: 0
A7: =DATE(2025,3,1) + ROW(A6) - 1 -> 45722 | B7: =TEXT(A7,"dddd") -> יום חמישי | C7: 337 | D7: 534 | F7: 11 | G7: 451 | H7: 0
A8: =DATE(2025,3,1) + ROW(A7) - 1 -> 45723 | B8: =TEXT(A8,"dddd") -> יום שישי | D8: 0 | E8: חופש | F8: 0
A9: =DATE(2025,3,1) + ROW(A8) - 1 -> 45724 | B9: =TEXT(A9,"dddd") -> שבת | D9: 0 | E9: חופש | F9: 0 | H9: 0
A10: =DATE(2025,3,1) + ROW(A9) - 1 -> 45725 | B10: =TEXT(A10,"dddd") -> יום ראשון | C10: 505 | D10: 608 | E10: שכר | F10: 11 | G10: 505 | H10: 1
A11: =DATE(2025,3,1) + ROW(A10) - 1 -> 45726 | B11: =TEXT(A11,"dddd") -> יום שני | C11: 369 | D11: 495 | E11: שכר | F11: 11 | G11: 394 | H11: 1
A12: =DATE(2025,3,1) + ROW(A11) - 1 -> 45727 | B12: =TEXT(A12,"dddd") -> יום שלישי | C12: 391 | D12: 367 | E12: שכר | F12: 11 | G12: 293 | H12: 1
A13: =DATE(2025,3,1) + ROW(A12) - 1 -> 45728 | B13: =TEXT(A13,"dddd") -> יום רביעי | C13: 323 | D13: 327 | E13: שכר | F13: 11 | G13: 276 | H13: 1
A14: =DATE(2025,3,1) + ROW(A13) - 1 -> 45729 | B14: =TEXT(A14,"dddd") -> יום חמישי | C14: 361 | D14: 303 | E14: שכר | F14: 11 | G14: 258 | H14: 1
A15: =DATE(2025,3,1) + ROW(A14) - 1 -> 45730 | B15: =TEXT(A15,"dddd") -> יום שישי | D15: 0 | E15: חופש | F15: 0 | H15: 0
A16: =DATE(2025,3,1) + ROW(A15) - 1 -> 45731 | B16: =TEXT(A16,"dddd") -> שבת | D16: 0 | E16: חופש | F16: 0 | H16: 0
A17: =DATE(2025,3,1) + ROW(A16) - 1 -> 45732 | B17: =TEXT(A17,"dddd") -> יום ראשון | C17: 261 | D17: 252 | F17: 11 | G17: 220 | H17: 0
A18: =DATE(2025,3,1) + ROW(A17) - 1 -> 45733 | B18: =TEXT(A18,"dddd") -> יום שני | C18: 350 | D18: 376 | F18: 11 | G18: 298 | H18: 0
A19: =DATE(2025,3,1) + ROW(A18) - 1 -> 45734 | B19: =TEXT(A19,"dddd") -> יום שלישי | C19: 300 | D19: 280 | F19: 11 | G19: 237 | H19: 0
A20: =DATE(2025,3,1) + ROW(A19) - 1 -> 45735 | B20: =TEXT(A20,"dddd") -> יום רביעי | C20: 295 | D20: 292 | F20: 11 | G20: 243 | H20: 0
A21: =DATE(2025,3,1) + ROW(A20) - 1 -> 45736 | B21: =TEXT(A21,"dddd") -> יום חמישי | C21: 332 | D21: 274 | F21: 11 | G21: 228 | H21: 0
A22: =DATE(2025,3,1) + ROW(A21) - 1 -> 45737 | B22: =TEXT(A22,"dddd") -> יום שישי | C22: 0 | D22: 0 | E22: חופש | F22: 0 | H22: 0
A23: =DATE(2025,3,1) + ROW(A22) - 1 -> 45738 | B23: =TEXT(A23,"dddd") -> שבת | C23: 0 | D23: 0 | E23: חופש | F23: 0 | H23: 0
A24: =DATE(2025,3,1) + ROW(A23) - 1 -> 45739 | B24: =TEXT(A24,"dddd") -> יום ראשון | C24: 316 | D24: 311 | F24: 8 | G24: 257 | H24: 0
A25: =DATE(2025,3,1) + ROW(A24) - 1 -> 45740 | B25: =TEXT(A25,"dddd") -> יום שני | C25: 277 | D25: 296 | F25: 9 | G25: 249 | H25: 0
A26: =DATE(2025,3,1) + ROW(A25) - 1 -> 45741 | B26: =TEXT(A26,"dddd") -> יום שלישי | C26: 227 | D26: 308 | F26: 8 | G26: 253 | H26: 0
A27: =DATE(2025,3,1) + ROW(A26) - 1 -> 45742 | B27: =TEXT(A27,"dddd") -> יום רביעי | C27: 301 | D27: 303 | F27: 8 | G27: 257 | H27: 0
A28: =DATE(2025,3,1) + ROW(A27) - 1 -> 45743 | B28: =TEXT(A28,"dddd") -> יום חמישי | C28: 242 | D28: 287 | F28: 10 | G28: 253 | H28: 0
A29: =DATE(2025,3,1) + ROW(A28) - 1 -> 45744 | B29: =TEXT(A29,"dddd") -> יום שישי | C29: 0 | D29: 0 | E29: חופש | F29: 0 | H29: 0
A30: =DATE(2025,3,1) + ROW(A29) - 1 -> 45745 | B30: =TEXT(A30,"dddd") -> שבת | C30: 0 | D30: 0 | E30: חופש | F30: 0 | H30: 0
A31: =DATE(2025,3,1) + ROW(A30) - 1 -> 45746 | B31: =TEXT(A31,"dddd") -> יום ראשון | C31: 339 | D31: 525 | E31: נוכחות | F31: 10 | G31: 379 | H31: 1
A32: =DATE(2025,3,1) + ROW(A31) - 1 -> 45747 | B32: =TEXT(A32,"dddd") -> יום שני | C32: 440 | D32: 541 | E32: נוכחות | F32: 8 | G32: 411 | H32: 1

Sheet אפריל 25
A1: תאריך | B1: יום | C1: פניות כתובות נפתחו | D1: שיחות נכנסות | E1: הערות | F1: מספר נציגים | G1: שיחות ללא כפילויות | H1: פיק
A2: =DATE(2025,4,1) + ROW(A1) - 1 -> 45748 | B2: =TEXT(A2,"dddd") -> יום שלישי | C2: 316 | D2: 522 | E2: נוכחות | F2: 14 | G2: 364 | H2: 1
A3: =DATE(2025,4,1) + ROW(A2) - 1 -> 45749 | B3: =TEXT(A3,"dddd") -> יום רביעי | C3: 199 | D3: 239 | F3: 8 | G3: 208 | H3: 0
A4: =DATE(2025,4,1) + ROW(A3) - 1 -> 45750 | B4: =TEXT(A4,"dddd") -> יום חמישי | C4: 157 | D4: 197 | F4: 7 | G4: 177 | H4: 0
A5: =DATE(2025,4,1) + ROW(A4) - 1 -> 45751 | B5: =TEXT(A5,"dddd") -> יום שישי | C5: 12 | D5: 0 | E5: חופש | F5: 0 | H5: 0
A6: =DATE(2025,4,1) + ROW(A5) - 1 -> 45752 | B6: =TEXT(A6,"dddd") -> שבת | C6: 4 | D6: 0 | E6: חופש | F6: 0 | H6: 0
A7: =DATE(2025,4,1) + ROW(A6) - 1 -> 45753 | B7: =TEXT(A7,"dddd") -> יום ראשון | C7: 239 | D7: 255 | F7: 10 | G7: 208 | H7: 0
A8: =DATE(2025,4,1) + ROW(A7) - 1 -> 45754 | B8: =TEXT(A8,"dddd") -> יום שני | C8: 280 | D8: 291 | E8: חופש | H8: 0
A9: =DATE(2025,4,1) + ROW(A8) - 1 -> 45755 | B9: =TEXT(A9,"dddd") -> יום שלישי | C9: 413 | D9: 582 | E9: שכר | F9: 10 | G9: 433 | H9: 1
A10: =DATE(2025,4,1) + ROW(A9) - 1 -> 45756 | B10: =TEXT(A10,"dddd") -> יום רביעי | C10: 401 | D10: 420 | E10: שכר | F10: 10 | G10: 315 | H10: 1
A11: =DATE(2025,4,1) + ROW(A10) - 1 -> 45757 | B11: =TEXT(A11,"dddd") -> יום חמישי | C11: 323 | D11: 320 | E11: שכר | F11: 9 | G11: 260 | H11: 1
A12: =DATE(2025,4,1) + ROW(A11) - 1 -> 45758 | B12: =TEXT(A12,"dddd") -> יום שישי | C12: 19 | D12: 0 | E12: חופש | F12: 0 | H12: 0
A13: =DATE(2025,4,1) + ROW(A12) - 1 -> 45759 | B13: =TEXT(A13,"dddd") -> שבת | C13: 0 | D13: 0 | E13: חופש | F13: 0 | H13: 0
A14: =DATE(2025,4,1) + ROW(A13) - 1 -> 45760 | B14: =TEXT(A14,"dddd") -> יום ראשון | C14: 5 | D14: 0 | E14: חופש | F14: 0 | H14: 0
A15: =DATE(2025,4,1) + ROW(A14) - 1 -> 45761 | B15: =TEXT(A15,"dddd") -> יום שני | C15: 98 | D15: 85 | E15: חופש | F15: 0 | H15: 0
A16: =DATE(2025,4,1) + ROW(A15) - 1 -> 45762 | B16: =TEXT(A16,"dddd") -> יום שלישי | C16: 70 | D16: 106 | E16: חופש | F16: 0 | H16: 0
A17: =DATE(2025,4,1) + ROW(A16) - 1 -> 45763 | B17: =TEXT(A17,"dddd") -> יום רביעי | C17: 113 | D17: 115 | E17: חופש | F17: 0 | H17: 0
A18: =DATE(2025,4,1) + ROW(A17) - 1 -> 45764 | B18: =TEXT(A18,"dddd") -> יום חמישי | C18: 44 | D18: 35 | E18: חופש | F18: 0 | H18: 0
A19: =DATE(2025,4,1) + ROW(A18) - 1 -> 45765 | B19: =TEXT(A19,"dddd") -> יום שישי | C19: 2 | D19: 0 | E19: חופש | F19: 0 | H19: 0
A20: =DATE(2025,4,1) + ROW(A19) - 1 -> 45766 | B20: =TEXT(A20,"dddd") -> שבת | C20: 4 | D20: 0 | E20: חופש | F20: 0 | H20: 0
A21: =DATE(2025,4,1) + ROW(A20) - 1 -> 45767 | B21: =TEXT(A21,"dddd") -> יום ראשון | C21: 580 | D21: 587 | F21: 8 | G21: 387 | H21: 0
A22: =DATE(2025,4,1) + ROW(A21) - 1 -> 45768 | B22: =TEXT(A22,"dddd") -> יום שני | C22: 480 | D22: 441 | F22: 10 | G22: 353 | H22: 0
A23: =DATE(2025,4,1) + ROW(A22) - 1 -> 45769 | B23: =TEXT(A23,"dddd") -> יום שלישי | C23: 388 | D23: 448 | F23: 10 | G23: 84 | H23: 0
A24: =DATE(2025,4,1) + ROW(A23) - 1 -> 45770 | B24: =TEXT(A24,"dddd") -> יום רביעי | C24: 305 | D24: 334 | F24: 12 | G24: 283 | H24: 0
A25: =DATE(2025,4,1) + ROW(A24) - 1 -> 45771 | B25: =TEXT(A25,"dddd") -> יום חמישי | C25: 381 | D25: 328 | F25: 10 | G25: 280 | H25: 0
A26: =DATE(2025,4,1) + ROW(A25) - 1 -> 45772 | B26: =TEXT(A26,"dddd") -> יום שישי | C26: 22 | D26: 0 | E26: חופש | F26: 0 | H26: 0
A27: =DATE(2025,4,1) + ROW(A26) - 1 -> 45773 | B27: =TEXT(A27,"dddd") -> שבת | C27: 10 | D27: 0 | E27: חופש | F27: 0 | H27: 0
A28: =DATE(2025,4,1) + ROW(A27) - 1 -> 45774 | B28: =TEXT(A28,"dddd") -> יום ראשון | C28: 402 | D28: 374 | E28: נוכחות | F28: 12 | G28: 327 | H28: 1
A29: =DATE(2025,4,1) + ROW(A28) - 1 -> 45775 | B29: =TEXT(A29,"dddd") -> יום שני | C29: 397 | D29: 404 | E29: נוכחות | F29: 11 | G29: 335 | H29: 1
A30: =DATE(2025,4,1) + ROW(A29) - 1 -> 45776 | B30: =TEXT(A30,"dddd") -> יום שלישי | C30: 374 | D30: 513 | E30: נוכחות | F30: 13 | G30: 410 | H30: 1
A31: =DATE(2025,4,1) + ROW(A30) - 1 -> 45777 | B31: =TEXT(A31,"dddd") -> יום רביעי | C31: 57 | D31: 3 | E31: חופש | F31: 0 | H31: 0

Sheet מאי 25
A1: תאריך | B1: יום | C1: פניות כתובות נפתחו | D1: שיחות נכנסות | E1: הערות | F1: מספר נציגים | G1: שיחות ללא כפילויות | H1: פיק
A2: =DATE(2025,5,1) + ROW(A1) - 1 -> 45778 | B2: =TEXT(A2,"dddd") -> יום חמישי | C2: 7 | D2: 3 | E2: חופש | F2: 0 | H2: 0
A3: =DATE(2025,5,1) + ROW(A2) - 1 -> 45779 | B3: =TEXT(A3,"dddd") -> יום שישי | C3: 26 | D3: 0 | E3: חופש | F3: 0 | H3: 0
A4: =DATE(2025,5,1) + ROW(A3) - 1 -> 45780 | B4: =TEXT(A4,"dddd") -> שבת | C4: 6 | D4: 0 | E4: חופש | F4: 0 | H4: 0
A5: =DATE(2025,5,1) + ROW(A4) - 1 -> 45781 | B5: =TEXT(A5,"dddd") -> יום ראשון | C5: 423 | D5: 461 | F5: 10 | G5: 354 | H5: 0
A6: =DATE(2025,5,1) + ROW(A5) - 1 -> 45782 | B6: =TEXT(A6,"dddd") -> יום שני | C6: 267 | D6: 297 | F6: 11 | G6: 256 | H6: 0
A7: =DATE(2025,5,1) + ROW(A6) - 1 -> 45783 | B7: =TEXT(A7,"dddd") -> יום שלישי | C7: 297 | D7: 270 | F7: 12 | G7: 239 | H7: 0
A8: =DATE(2025,5,1) + ROW(A7) - 1 -> 45784 | B8: =TEXT(A8,"dddd") -> יום רביעי | C8: 358 | D8: 472 | E8: שכר | F8: 9 | G8: 397 | H8: 1
A9: =DATE(2025,5,1) + ROW(A8) - 1 -> 45785 | B9: =TEXT(A9,"dddd") -> יום חמישי | C9: 323 | D9: 583 | E9: שכר | F9: 11 | G9: 602 | H9: 1
A10: =DATE(2025,5,1) + ROW(A9) - 1 -> 45786 | B10: =TEXT(A10,"dddd") -> יום שישי | C10: 20 | D10: 0 | E10: חופש | F10: 0 | H10: 0
A11: =DATE(2025,5,1) + ROW(A10) - 1 -> 45787 | B11: =TEXT(A11,"dddd") -> שבת | C11: 9 | D11: 0 | E11: חופש | F11: 0 | H11: 0
A12: =DATE(2025,5,1) + ROW(A11) - 1 -> 45788 | B12: =TEXT(A12,"dddd") -> יום ראשון | C12: 409 | D12: 546 | E12: שכר | F12: 9 | G12: 231 | H12: 1
A13: =DATE(2025,5,1) + ROW(A12) - 1 -> 45789 | B13: =TEXT(A13,"dddd") -> יום שני | C13: 372 | D13: 503 | E13: שכר | F13: 8 | G13: 379 | H13: 1
A14: =DATE(2025,5,1) + ROW(A13) - 1 -> 45790 | B14: =TEXT(A14,"dddd") -> יום שלישי | C14: 276 | D14: 428 | E14: שכר | F14: 7 | G14: 334 | H14: 1
A15: =DATE(2025,5,1) + ROW(A14) - 1 -> 45791 | B15: =TEXT(A15,"dddd") -> יום רביעי | C15: 271 | D15: 389 | F15: 5 | G15: 302 | H15: 0
A16: =DATE(2025,5,1) + ROW(A15) - 1 -> 45792 | B16: =TEXT(A16,"dddd") -> יום חמישי | C16: 265 | D16: 329 | F16: 5 | G16: 265 | H16: 0
A17: =DATE(2025,5,1) + ROW(A16) - 1 -> 45793 | B17: =TEXT(A17,"dddd") -> יום שישי | C17: 26 | D17: 0 | E17: חופש | F17: 0 | H17: 0
A18: =DATE(2025,5,1) + ROW(A17) - 1 -> 45794 | B18: =TEXT(A18,"dddd") -> שבת | C18: 7 | D18: 0 | E18: חופש | F18: 0 | H18: 0
A19: =DATE(2025,5,1) + ROW(A18) - 1 -> 45795 | B19: =TEXT(A19,"dddd") -> יום ראשון | C19: 51 | D19: 4 | E19: חופש | F19: 0 | H19: 0
A20: =DATE(2025,5,1) + ROW(A19) - 1 -> 45796 | B20: =TEXT(A20,"dddd") -> יום שני | C20: 651 | D20: 800 | F20: 11 | G20: 230 | H20: 0
A21: =DATE(2025,5,1) + ROW(A20) - 1 -> 45797 | B21: =TEXT(A21,"dddd") -> יום שלישי | C21: 410 | D21: 606 | F21: 10 | G21: 116 | H21: 0
A22: =DATE(2025,5,1) + ROW(A21) - 1 -> 45798 | B22: =TEXT(A22,"dddd") -> יום רביעי | C22: 299 | D22: 456 | F22: 9 | G22: 182 | H22: 0
A23: =DATE(2025,5,1) + ROW(A22) - 1 -> 45799 | B23: =TEXT(A23,"dddd") -> יום חמישי | C23: 256 | D23: 457 | F23: 8 | G23: 382 | H23: 0
A24: =DATE(2025,5,1) + ROW(A23) - 1 -> 45800 | B24: =TEXT(A24,"dddd") -> יום שישי | C24: 65 | D24: 0 | E24: חופש | F24: 0 | H24: 0
A25: =DATE(2025,5,1) + ROW(A24) - 1 -> 45801 | B25: =TEXT(A25,"dddd") -> שבת | C25: 7 | D25: 0 | E25: חופש | F25: 0 | H25: 0
A26: =DATE(2025,5,1) + ROW(A25) - 1 -> 45802 | B26: =TEXT(A26,"dddd") -> יום ראשון | C26: 328 | D26: 642 | F26: 6 | G26: 438 | H26: 0
A27: =DATE(2025,5,1) + ROW(A26) - 1 -> 45803 | B27: =TEXT(A27,"dddd") -> יום שני | C27: 428 | D27: 547 | F27: 7 | G27: 401 | H27: 0
A28: =DATE(2025,5,1) + ROW(A27) - 1 -> 45804 | B28: =TEXT(A28,"dddd") -> יום שלישי | C28: 345 | D28: 614 | F28: 7 | G28: 383 | H28: 0
A29: =DATE(2025,5,1) + ROW(A28) - 1 -> 45805 | B29: =TEXT(A29,"dddd") -> יום רביעי | C29: 310 | D29: 580 | E29: נוכחות | F29: 6 | G29: 399 | H29: 1
A30: =DATE(2025,5,1) + ROW(A29) - 1 -> 45806 | B30: =TEXT(A30,"dddd") -> יום חמישי | C30: 353 | D30: 603 | E30: נוכחות | F30: 9 | G30: 281 | H30: 1
A31: =DATE(2025,5,1) + ROW(A30) - 1 -> 45807 | B31: =TEXT(A31,"dddd") -> יום שישי | C31: 72 | D31: 0 | E31: חופש | F31: 0 | H31: 0
A32: =DATE(2025,5,1) + ROW(A31) - 1 -> 45808 | B32: =TEXT(A32,"dddd") -> שבת | C32: 5 | D32: 0 | E32: חופש | F32: 0 | H32: 0

Sheet יוני 25
A1: תאריך | B1: יום | C1: פניות כתובות נפתחו | D1: שיחות נכנסות | E1: הערות | F1: מספר נציגים | G1: שיחות ללא כפילויות | H1: פיק
A2: =DATE(2025,6,1) + ROW(A1) - 1 -> 45809 | B2: =TEXT(A2,"dddd") -> יום ראשון | C2: 29 | D2: 0 | E2: חופש | F2: 0 | H2: 0
A3: =DATE(2025,6,1) + ROW(A2) - 1 -> 45810 | B3: =TEXT(A3,"dddd") -> יום שני | C3: 8 | D3: 0 | E3: חופש | F3: 0 | H3: 0
A4: =DATE(2025,6,1) + ROW(A3) - 1 -> 45811 | B4: =TEXT(A4,"dddd") -> יום שלישי | C4: 524 | D4: 681 | F4: 7 | G4: 496 | H4: 0
A5: =DATE(2025,6,1) + ROW(A4) - 1 -> 45812 | B5: =TEXT(A5,"dddd") -> יום רביעי | C5: 192 | D5: 350 | F5: 7 | G5: 280 | H5: 0
A6: =DATE(2025,6,1) + ROW(A5) - 1 -> 45813 | B6: =TEXT(A6,"dddd") -> יום חמישי | C6: 226 | D6: 262 | F6: 8 | G6: 238 | H6: 0
A7: =DATE(2025,6,1) + ROW(A6) - 1 -> 45814 | B7: =TEXT(A7,"dddd") -> יום שישי | E7: חופש | F7: 0 | H7: 0
A8: =DATE(2025,6,1) + ROW(A7) - 1 -> 45815 | B8: =TEXT(A8,"dddd") -> שבת | E8: חופש | F8: 0 | H8: 0
A9: =DATE(2025,6,1) + ROW(A8) - 1 -> 45816 | B9: =TEXT(A9,"dddd") -> יום ראשון | C9: 401 | D9: 424 | E9: שכר | F9: 8 | G9: 361 | H9: 1
A10: =DATE(2025,6,1) + ROW(A9) - 1 -> 45817 | B10: =TEXT(A10,"dddd") -> יום שני | C10: 471 | D10: 904 | E10: שכר | F10: 8 | G10: 660 | H10: 1
A11: =DATE(2025,6,1) + ROW(A10) - 1 -> 45818 | B11: =TEXT(A11,"dddd") -> יום שלישי | C11: 358 | D11: 490 | E11: שכר | F11: 9 | G11: 403 | H11: 1
A12: =DATE(2025,6,1) + ROW(A11) - 1 -> 45819 | B12: =TEXT(A12,"dddd") -> יום רביעי | C12: 288 | D12: 285 | E12: שכר | F12: 9 | G12: 260 | H12: 1
A13: =DATE(2025,6,1) + ROW(A12) - 1 -> 45820 | B13: =TEXT(A13,"dddd") -> יום חמישי | C13: 249 | D13: 250 | E13: שכר | F13: 9 | G13: 223 | H13: 1
A14: =DATE(2025,6,1) + ROW(A13) - 1 -> 45821 | B14: =TEXT(A14,"dddd") -> יום שישי | C14: 0 | D14: 0 | E14: חופש | F14: 0 | H14: 0
A15: =DATE(2025,6,1) + ROW(A14) - 1 -> 45822 | B15: =TEXT(A15,"dddd") -> שבת | C15: 0 | D15: 0 | E15: חופש | F15: 0 | H15: 0
A16: =DATE(2025,6,1) + ROW(A15) - 1 -> 45823 | B16: =TEXT(A16,"dddd") -> יום ראשון | C16: 0 | D16: 0 | E16: חופש | F16: 0 | H16: 0
A17: =DATE(2025,6,1) + ROW(A16) - 1 -> 45824 | B17: =TEXT(A17,"dddd") -> יום שני | C17: 0 | D17: 0 | E17: חופש | F17: 0 | H17: 0
A18: =DATE(2025,6,1) + ROW(A17) - 1 -> 45825 | B18: =TEXT(A18,"dddd") -> יום שלישי | C18: 0 | D18: 0 | E18: חופש | F18: 0 | H18: 0
A19: =DATE(2025,6,1) + ROW(A18) - 1 -> 45826 | B19: =TEXT(A19,"dddd") -> יום רביעי | C19: 0 | D19: 0 | E19: חופש | F19: 0 | H19: 0
A20: =DATE(2025,6,1) + ROW(A19) - 1 -> 45827 | B20: =TEXT(A20,"dddd") -> יום חמישי | C20: 0 | D20: 0 | E20: חופש | F20: 0 | H20: 0
A21: =DATE(2025,6,1) + ROW(A20) - 1 -> 45828 | B21: =TEXT(A21,"dddd") -> יום שישי | C21: 0 | D21: 0 | E21: חופש | F21: 0 | H21: 0
A22: =DATE(2025,6,1) + ROW(A21) - 1 -> 45829 | B22: =TEXT(A22,"dddd") -> שבת | C22: 0 | D22: 0 | E22: חופש | F22: 0 | H22: 0
A23: =DATE(2025,6,1) + ROW(A22) - 1 -> 45830 | B23: =TEXT(A23,"dddd") -> יום ראשון | C23: 0 | D23: 0 | E23: חופש | F23: 0 | H23: 0
A24: =DATE(2025,6,1) + ROW(A23) - 1 -> 45831 | B24: =TEXT(A24,"dddd") -> יום שני | C24: 0 | D24: 0 | E24: חופש | F24: 0 | H24: 0
A25: =DATE(2025,6,1) + ROW(A24) - 1 -> 45832 | B25: =TEXT(A25,"dddd") -> יום שלישי | C25: 0 | D25: 0 | E25: חופש | F25: 0 | H25: 0
A26: =DATE(2025,6,1) + ROW(A25) - 1 -> 45833 | B26: =TEXT(A26,"dddd") -> יום רביעי | C26: 553 | D26: 633 | F26: 7 | G26: 498 | H26: 0
A27: =DATE(2025,6,1) + ROW(A26) - 1 -> 45834 | B27: =TEXT(A27,"dddd") -> יום חמישי | C27: 285 | D27: 581 | F27: 7 | G27: 449 | H27: 0
A28: =DATE(2025,6,1) + ROW(A27) - 1 -> 45835 | B28: =TEXT(A28,"dddd") -> יום שישי | E28: חופש | H28: 0
A29: =DATE(2025,6,1) + ROW(A28) - 1 -> 45836 | B29: =TEXT(A29,"dddd") -> שבת | E29: חופש | H29: 0
A30: =DATE(2025,6,1) + ROW(A29) - 1 -> 45837 | B30: =TEXT(A30,"dddd") -> יום ראשון | C30: 749 | D30: 835 | E30: נוכחות | F30: 6 | G30: 610 | H30: 1
A31: =DATE(2025,6,1) + ROW(A30) - 1 -> 45838 | B31: =TEXT(A31,"dddd") -> יום שני | E31: נוכחות | F31: 7 | H31: 1

Sheet יולי 25
A1: תאריך | B1: יום | C1: פניות כתובות נפתחו | D1: שיחות נכנסות | E1: הערות | F1: מספר נציגים | G1: שיחות ללא כפילויות | H1: פיק
A2: =DATE(2025,7,1) + ROW(A1) - 1 -> 45839 | B2: =TEXT(A2,"dddd") -> יום שלישי | C2: 255 | D2: 701 | F2: 8 | G2: 459 | H2: 0
A3: =DATE(2025,7,1) + ROW(A2) - 1 -> 45840 | B3: =TEXT(A3,"dddd") -> יום רביעי | C3: 182 | D3: 329 | F3: 8 | G3: 264 | H3: 0
A4: =DATE(2025,7,1) + ROW(A3) - 1 -> 45841 | B4: =TEXT(A4,"dddd") -> יום חמישי | C4: 245 | F4: 8 | G4: 191 | H4: 0
A5: =DATE(2025,7,1) + ROW(A4) - 1 -> 45842 | B5: =TEXT(A5,"dddd") -> יום שישי | E5: חופש | H5: 0
A6: =DATE(2025,7,1) + ROW(A5) - 1 -> 45843 | B6: =TEXT(A6,"dddd") -> שבת | E6: חופש | H6: 0
A7: =DATE(2025,7,1) + ROW(A6) - 1 -> 45844 | B7: =TEXT(A7,"dddd") -> יום ראשון | C7: 291 | D7: 255 | F7: 8 | G7: 225 | H7: 0
A8: =DATE(2025,7,1) + ROW(A7) - 1 -> 45845 | B8: =TEXT(A8,"dddd") -> יום שני | C8: 206 | D8: 520 | E8: שכר | F8: 8 | G8: 417 | H8: 1
A9: =DATE(2025,7,1) + ROW(A8) - 1 -> 45846 | B9: =TEXT(A9,"dddd") -> יום שלישי | C9: 438 | D9: 400 | E9: שכר | F9: 8 | G9: 333 | H9: 1
A10: =DATE(2025,7,1) + ROW(A9) - 1 -> 45847 | B10: =TEXT(A10,"dddd") -> יום רביעי | C10: 117 | D10: 335 | E10: שכר | F10: 8 | G10: 274 | H10: 1
A11: =DATE(2025,7,1) + ROW(A10) - 1 -> 45848 | B11: =TEXT(A11,"dddd") -> יום חמישי | C11: 296 | D11: 293 | E11: שכר | F11: 8 | G11: 247 | H11: 1
A12: =DATE(2025,7,1) + ROW(A11) - 1 -> 45849 | B12: =TEXT(A12,"dddd") -> יום שישי | E12: חופש | H12: 1
A13: =DATE(2025,7,1) + ROW(A12) - 1 -> 45850 | B13: =TEXT(A13,"dddd") -> שבת | E13: חופש | H13: 0
A14: =DATE(2025,7,1) + ROW(A13) - 1 -> 45851 | B14: =TEXT(A14,"dddd") -> יום ראשון | C14: 220 | D14: 305 | F14: 8 | G14: 254 | H14: 0
A15: =DATE(2025,7,1) + ROW(A14) - 1 -> 45852 | B15: =TEXT(A15,"dddd") -> יום שני | C15: 664 | D15: 282 | F15: 8 | G15: 220 | H15: 0
A16: =DATE(2025,7,1) + ROW(A15) - 1 -> 45853 | B16: =TEXT(A16,"dddd") -> יום שלישי | C16: 374 | D16: 276 | F16: 8 | G16: 235 | H16: 0
A17: =DATE(2025,7,1) + ROW(A16) - 1 -> 45854 | B17: =TEXT(A17,"dddd") -> יום רביעי | C17: 299 | D17: 238 | F17: 8 | G17: 200 | H17: 0
A18: =DATE(2025,7,1) + ROW(A17) - 1 -> 45855 | B18: =TEXT(A18,"dddd") -> יום חמישי | C18: 254 | D18: 227 | F18: 8 | G18: 201 | H18: 0
A19: =DATE(2025,7,1) + ROW(A18) - 1 -> 45856 | B19: =TEXT(A19,"dddd") -> יום שישי | E19: חופש | H19: 0
A20: =DATE(2025,7,1) + ROW(A19) - 1 -> 45857 | B20: =TEXT(A20,"dddd") -> שבת | E20: חופש | H20: 0
A21: =DATE(2025,7,1) + ROW(A20) - 1 -> 45858 | B21: =TEXT(A21,"dddd") -> יום ראשון | C21: 14 | E21: חופש | H21: 0
A22: =DATE(2025,7,1) + ROW(A21) - 1 -> 45859 | B22: =TEXT(A22,"dddd") -> יום שני | C22: 364 | D22: 317 | F22: 8 | G22: 268 | H22: 0
A23: =DATE(2025,7,1) + ROW(A22) - 1 -> 45860 | B23: =TEXT(A23,"dddd") -> יום שלישי | C23: 315 | D23: 296 | F23: 8 | G23: 256 | H23: 0
A24: =DATE(2025,7,1) + ROW(A23) - 1 -> 45861 | B24: =TEXT(A24,"dddd") -> יום רביעי | C24: 284 | D24: 283 | F24: 8 | G24: 238 | H24: 0
A25: =DATE(2025,7,1) + ROW(A24) - 1 -> 45862 | B25: =TEXT(A25,"dddd") -> יום חמישי | C25: 352 | D25: 283 | F25: 8 | G25: 237 | H25: 0
A26: =DATE(2025,7,1) + ROW(A25) - 1 -> 45863 | B26: =TEXT(A26,"dddd") -> יום שישי | E26: חופש | H26: 0
A27: =DATE(2025,7,1) + ROW(A26) - 1 -> 45864 | B27: =TEXT(A27,"dddd") -> שבת | E27: חופש | H27: 0
A28: =DATE(2025,7,1) + ROW(A27) - 1 -> 45865 | B28: =TEXT(A28,"dddd") -> יום ראשון | C28: 291 | D28: 325 | F28: 8 | G28: 285 | H28: 0
A29: =DATE(2025,7,1) + ROW(A28) - 1 -> 45866 | B29: =TEXT(A29,"dddd") -> יום שני | C29: 460 | D29: 418 | E29: נוכחות | F29: 8 | G29: 344 | H29: 1
A30: =DATE(2025,7,1) + ROW(A29) - 1 -> 45867 | B30: =TEXT(A30,"dddd") -> יום שלישי | C30: 301 | D30: 385 | E30: נוכחות | F30: 8 | G30: 320 | H30: 1
A31: =DATE(2025,7,1) + ROW(A30) - 1 -> 45868 | B31: =TEXT(A31,"dddd") -> יום רביעי | C31: 387 | D31: 369 | E31: נוכחות | F31: 8 | G31: 301 | H31: 1
A32: =DATE(2025,7,1) + ROW(A31) - 1 -> 45869 | B32: =TEXT(A32,"dddd") -> יום חמישי | C32: 375 | D32: 458 | E32: נוכחות | F32: 8 | G32: 371 | H32: 1

Sheet אוגוסט 24
A1: תאריך | B1: יום | C1: פניות כתובות נפתחו | D1: שיחות נכנסות | E1: הערות | F1: מספר נציגים | G1: שיחות ללא כפילויות | H1: עזר | I1: אחוז
A2: =DATE(2024,8,1) + ROW(A1) - 1 -> 45505 | B2: =TEXT(A2,"dddd") -> יום חמישי | C2: 194 | D2: 339 | F2: 14 | G2: 301 | H2: =D2-G2 -> 38 | I2: =H2/D2 -> 0.1120944
A3: =DATE(2024,8,1) + ROW(A2) - 1 -> 45506 | B3: =TEXT(A3,"dddd") -> יום שישי | E3: חופש | H3: =D3-G3 -> 0 | I3: 0
A4: =DATE(2024,8,1) + ROW(A3) - 1 -> 45507 | B4: =TEXT(A4,"dddd") -> שבת | E4: חופש | H4: =D4-G4 -> 0 | I4: 0
A5: =DATE(2024,8,1) + ROW(A4) - 1 -> 45508 | B5: =TEXT(A5,"dddd") -> יום ראשון | C5: 220 | D5: 272 | F5: 11 | G5: 229 | H5: =D5-G5 -> 43 | I5: =H5/D5 -> 0.15808824
A6: =DATE(2024,8,1) + ROW(A5) - 1 -> 45509 | B6: =TEXT(A6,"dddd") -> יום שני | C6: 200 | D6: 239 | G6: 214 | H6: =D6-G6 -> 25 | I6: =H6/D6 -> 0.10460251
A7: =DATE(2024,8,1) + ROW(A6) - 1 -> 45510 | B7: =TEXT(A7,"dddd") -> יום שלישי | C7: 168 | D7: 192 | F7: 9 | G7: 178 | H7: =D7-G7 -> 14 | I7: =H7/D7 -> 0.072916667
A8: =DATE(2024,8,1) + ROW(A7) - 1 -> 45511 | B8: =TEXT(A8,"dddd") -> יום רביעי | C8: 298 | D8: 596 | E8: תלוש | F8: 15 | G8: 505 | H8: =D8-G8 -> 91 | I8: =H8/D8 -> 0.15268456
A9: =DATE(2024,8,1) + ROW(A8) - 1 -> 45512 | B9: =TEXT(A9,"dddd") -> יום חמישי | C9: 277 | D9: 369 | E9: שכר | F9: 12 | G9: 308 | H9: =D9-G9 -> 61 | I9: =H9/D9 -> 0.16531165
A10: =DATE(2024,8,1) + ROW(A9) - 1 -> 45513 | B10: =TEXT(A10,"dddd") -> יום שישי | E10: חופש | H10: =D10-G10 -> 0 | I10: 0
A11: =DATE(2024,8,1) + ROW(A10) - 1 -> 45514 | B11: =TEXT(A11,"dddd") -> שבת | E11: חופש | H11: =D11-G11 -> 0 | I11: 0
A12: =DATE(2024,8,1) + ROW(A11) - 1 -> 45515 | B12: =TEXT(A12,"dddd") -> יום ראשון | C12: 341 | D12: 350 | E12: שכר | F12: 12 | G12: 299 | H12: =D12-G12 -> 51 | I12: =H12/D12 -> 0.14571429
A13: =DATE(2024,8,1) + ROW(A12) - 1 -> 45516 | B13: =TEXT(A13,"dddd") -> יום שני | C13: 265 | D13: 448 | E13: שכר | F13: 12 | G13: 384 | H13: =D13-G13 -> 64 | I13: =H13/D13 -> 0.14285714
A14: =DATE(2024,8,1) + ROW(A13) - 1 -> 45517 | B14: =TEXT(A14,"dddd") -> יום שלישי | C14: 214 | D14: 226 | E14: ט באב | F14: 9 | G14: 198 | H14: =D14-G14 -> 28 | I14: =H14/D14 -> 0.12389381
A15: =DATE(2024,8,1) + ROW(A14) - 1 -> 45518 | B15: =TEXT(A15,"dddd") -> יום רביעי | C15: 246 | D15: 265 | F15: 11 | G15: 224 | H15: =D15-G15 -> 41 | I15: =H15/D15 -> 0.15471698
A16: =DATE(2024,8,1) + ROW(A15) - 1 -> 45519 | B16: =TEXT(A16,"dddd") -> יום חמישי | C16: 179 | D16: 247 | F16: 12 | G16: 212 | H16: =D16-G16 -> 35 | I16: =H16/D16 -> 0.1417004
A17: =DATE(2024,8,1) + ROW(A16) - 1 -> 45520 | B17: =TEXT(A17,"dddd") -> יום שישי | E17: חופש | H17: =D17-G17 -> 0 | I17: 0
A18: =DATE(2024,8,1) + ROW(A17) - 1 -> 45521 | B18: =TEXT(A18,"dddd") -> שבת | E18: חופש | H18: =D18-G18 -> 0 | I18: 0
A19: =DATE(2024,8,1) + ROW(A18) - 1 -> 45522 | B19: =TEXT(A19,"dddd") -> יום ראשון | C19: 384 | D19: 342 | F19: 13 | G19: 297 | H19: =D19-G19 -> 45 | I19: =H19/D19 -> 0.13157895
A20: =DATE(2024,8,1) + ROW(A19) - 1 -> 45523 | B20: =TEXT(A20,"dddd") -> יום שני | C20: 309 | D20: 266 | F20: 11 | G20: 244 | H20: =D20-G20 -> 22 | I20: =H20/D20 -> 0.082706767
A21: =DATE(2024,8,1) + ROW(A20) - 1 -> 45524 | B21: =TEXT(A21,"dddd") -> יום שלישי | C21: 282 | D21: 320 | F21: 15 | G21: 283 | H21: =D21-G21 -> 37 | I21: =H21/D21 -> 0.115625
A22: =DATE(2024,8,1) + ROW(A21) - 1 -> 45525 | B22: =TEXT(A22,"dddd") -> יום רביעי | C22: 337 | D22: 303 | F22: 11 | G22: 269 | H22: =D22-G22 -> 34 | I22: =H22/D22 -> 0.11221122
A23: =DATE(2024,8,1) + ROW(A22) - 1 -> 45526 | B23: =TEXT(A23,"dddd") -> יום חמישי | C23: 272 | D23: 423 | F23: 14 | G23: 380 | H23: =D23-G23 -> 43 | I23: =H23/D23 -> 0.10165485
A24: =DATE(2024,8,1) + ROW(A23) - 1 -> 45527 | B24: =TEXT(A24,"dddd") -> יום שישי | C24: 0 | D24: 0 | E24: חופש | H24: =D24-G24 -> 0 | I24: 0
A25: =DATE(2024,8,1) + ROW(A24) - 1 -> 45528 | B25: =TEXT(A25,"dddd") -> שבת | C25: 0 | D25: 0 | E25: חופש | H25: =D25-G25 -> 0 | I25: 0
A26: =DATE(2024,8,1) + ROW(A25) - 1 -> 45529 | B26: =TEXT(A26,"dddd") -> יום ראשון | C26: 267 | D26: 371 | F26: 10 | G26: 327 | H26: =D26-G26 -> 44 | I26: =H26/D26 -> 0.11859838
A27: =DATE(2024,8,1) + ROW(A26) - 1 -> 45530 | B27: =TEXT(A27,"dddd") -> יום שני | C27: 249 | D27: 329 | F27: 9 | G27: 291 | H27: =D27-G27 -> 38 | I27: =H27/D27 -> 0.11550152
A28: =DATE(2024,8,1) + ROW(A27) - 1 -> 45531 | B28: =TEXT(A28,"dddd") -> יום שלישי | C28: 217 | D28: 318 | F28: 11 | G28: 265 | H28: =D28-G28 -> 53 | I28: =H28/D28 -> 0.16666667
A29: =DATE(2024,8,1) + ROW(A28) - 1 -> 45532 | B29: =TEXT(A29,"dddd") -> יום רביעי | C29: 208 | D29: 383 | E29: נוכחות | F29: 12 | G29: 326 | H29: =D29-G29 -> 57 | I29: =H29/D29 -> 0.14882507
A30: =DATE(2024,8,1) + ROW(A29) - 1 -> 45533 | B30: =TEXT(A30,"dddd") -> יום חמישי | C30: 202 | D30: 322 | E30: נוכחות | F30: 13 | G30: 274 | H30: =D30-G30 -> 48 | I30: =H30/D30 -> 0.14906832
A31: =DATE(2024,8,1) + ROW(A30) - 1 -> 45534 | B31: =TEXT(A31,"dddd") -> יום שישי | E31: חופש | H31: =D31-G31 -> 0
A32: =DATE(2024,8,1) + ROW(A31) - 1 -> 45535 | B32: =TEXT(A32,"dddd") -> שבת | E32: חופש | H32: =D32-G32 -> 0
D33: =SUMPRODUCT(D2:D20,I2:I20)/SUM(D2:D20) -> 0.13442544

Sheet ספט 24
A1: תאריך | B1: יום | C1: פניות כתובות נפתחו | D1: שיחות נכנסות | E1: הערות | F1: מספר נציגים | G1: שיחות ללא כפילויות | H1: עזר | I1: אחוז
A2: =DATE(2024,9,1) + ROW(A1) - 1 -> 45536 | B2: =TEXT(A2,"dddd") -> יום ראשון | C2: 411 | D2: 597 | F2: 13 | G2: 515 | H2: =D2-G2 -> 82 | I2: =H2/D2 -> 0.13735343
A3: =DATE(2024,9,1) + ROW(A2) - 1 -> 45537 | B3: =TEXT(A3,"dddd") -> יום שני | C3: 187 | D3: 369 | F3: 12 | G3: 324 | H3: =D3-G3 -> 45 | I3: =H3/D3 -> 0.12195122
A4: =DATE(2024,9,1) + ROW(A3) - 1 -> 45538 | B4: =TEXT(A4,"dddd") -> יום שלישי | C4: 183 | D4: 305 | F4: 11 | G4: 269 | H4: =D4-G4 -> 36 | I4: =H4/D4 -> 0.11803279
A5: =DATE(2024,9,1) + ROW(A4) - 1 -> 45539 | B5: =TEXT(A5,"dddd") -> יום רביעי | C5: 181 | D5: 299 | F5: 15 | G5: 256 | H5: =D5-G5 -> 43 | I5: =H5/D5 -> 0.14381271
A6: =DATE(2024,9,1) + ROW(A5) - 1 -> 45540 | B6: =TEXT(A6,"dddd") -> יום חמישי | C6: 259 | D6: 562 | E6: תקשור היעדרות מלחמה | F6: 17 | G6: 489 | H6: =D6-G6 -> 73 | I6: =H6/D6 -> 0.12989324
A7: =DATE(2024,9,1) + ROW(A6) - 1 -> 45541 | B7: =TEXT(A7,"dddd") -> יום שישי | C7: 0 | D7: 0 | E7: חופש | H7: =D7-G7 -> 0 | I7: 0
A8: =DATE(2024,9,1) + ROW(A7) - 1 -> 45542 | B8: =TEXT(A8,"dddd") -> שבת | C8: 0 | D8: 0 | E8: חופש | H8: =D8-G8 -> 0 | I8: 0
A9: =DATE(2024,9,1) + ROW(A8) - 1 -> 45543 | B9: =TEXT(A9,"dddd") -> יום ראשון | C9: 321 | D9: 508 | E9: תלוש | F9: 16 | G9: 454 | H9: =D9-G9 -> 54 | I9: =H9/D9 -> 0.10629921
A10: =DATE(2024,9,1) + ROW(A9) - 1 -> 45544 | B10: =TEXT(A10,"dddd") -> יום שני | C10: 245 | D10: 370 | E10: שכר | F10: 14 | G10: 324 | H10: =D10-G10 -> 46 | I10: =H10/D10 -> 0.12432432
A11: =DATE(2024,9,1) + ROW(A10) - 1 -> 45545 | B11: =TEXT(A11,"dddd") -> יום שלישי | C11: 235 | D11: 353 | E11: שכר | F11: 11 | G11: 309 | H11: =D11-G11 -> 44 | I11: =H11/D11 -> 0.12464589
A12: =DATE(2024,9,1) + ROW(A11) - 1 -> 45546 | B12: =TEXT(A12,"dddd") -> יום רביעי | C12: 241 | D12: 279 | E12: שכר | F12: 12 | G12: 232 | H12: =D12-G12 -> 47 | I12: =H12/D12 -> 0.16845878
A13: =DATE(2024,9,1) + ROW(A12) - 1 -> 45547 | B13: =TEXT(A13,"dddd") -> יום חמישי | C13: 356 | D13: 270 | E13: שכר | F13: 9 | G13: 240 | H13: =D13-G13 -> 30 | I13: =H13/D13 -> 0.11111111
A14: =DATE(2024,9,1) + ROW(A13) - 1 -> 45548 | B14: =TEXT(A14,"dddd") -> יום שישי | C14: 0 | D14: 0 | E14: חופש | H14: =D14-G14 -> 0 | I14: 0
A15: =DATE(2024,9,1) + ROW(A14) - 1 -> 45549 | B15: =TEXT(A15,"dddd") -> שבת | C15: 0 | D15: 0 | E15: חופש | H15: =D15-G15 -> 0 | I15: 0
A16: =DATE(2024,9,1) + ROW(A15) - 1 -> 45550 | B16: =TEXT(A16,"dddd") -> יום ראשון | C16: 498 | D16: 376 | F16: 12 | G16: 311 | H16: =D16-G16 -> 65 | I16: =H16/D16 -> 0.17287234
A17: =DATE(2024,9,1) + ROW(A16) - 1 -> 45551 | B17: =TEXT(A17,"dddd") -> יום שני | C17: 312 | D17: 347 | F17: 9 | G17: 287 | H17: =D17-G17 -> 60 | I17: =H17/D17 -> 0.17291066
A18: =DATE(2024,9,1) + ROW(A17) - 1 -> 45552 | B18: =TEXT(A18,"dddd") -> יום שלישי | C18: 249 | D18: 289 | F18: 12 | G18: 259 | H18: =D18-G18 -> 30 | I18: =H18/D18 -> 0.10380623
A19: =DATE(2024,9,1) + ROW(A18) - 1 -> 45553 | B19: =TEXT(A19,"dddd") -> יום רביעי | C19: 228 | D19: 257 | F19: 11 | G19: 221 | H19: =D19-G19 -> 36 | I19: =H19/D19 -> 0.14007782
A20: =DATE(2024,9,1) + ROW(A19) - 1 -> 45554 | B20: =TEXT(A20,"dddd") -> יום חמישי | C20: 252 | D20: 266 | F20: 11 | G20: 239 | H20: =D20-G20 -> 27 | I20: =H20/D20 -> 0.10150376
A21: =DATE(2024,9,1) + ROW(A20) - 1 -> 45555 | B21: =TEXT(A21,"dddd") -> יום שישי | C21: 0 | D21: 0 | E21: חופש | H21: =D21-G21 -> 0 | I21: 0
A22: =DATE(2024,9,1) + ROW(A21) - 1 -> 45556 | B22: =TEXT(A22,"dddd") -> שבת | C22: 0 | D22: 0 | E22: חופש | H22: =D22-G22 -> 0 | I22: 0
A23: =DATE(2024,9,1) + ROW(A22) - 1 -> 45557 | B23: =TEXT(A23,"dddd") -> יום ראשון | C23: 309 | D23: 371 | F23: 13 | G23: 326 | H23: =D23-G23 -> 45 | I23: =H23/D23 -> 0.1212938
A24: =DATE(2024,9,1) + ROW(A23) - 1 -> 45558 | B24: =TEXT(A24,"dddd") -> יום שני | C24: 230 | D24: 308 | F24: 12 | G24: 275 | H24: =D24-G24 -> 33 | I24: =H24/D24 -> 0.10714286
A25: =DATE(2024,9,1) + ROW(A24) - 1 -> 45559 | B25: =TEXT(A25,"dddd") -> יום שלישי | C25: 224 | D25: 349 | F25: 12 | G25: 309 | H25: =D25-G25 -> 40 | I25: =H25/D25 -> 0.11461318
A26: =DATE(2024,9,1) + ROW(A25) - 1 -> 45560 | B26: =TEXT(A26,"dddd") -> יום רביעי | C26: 353 | D26: 431 | F26: 13 | G26: 393 | H26: =D26-G26 -> 38 | I26: =H26/D26 -> 0.088167053
A27: =DATE(2024,9,1) + ROW(A26) - 1 -> 45561 | B27: =TEXT(A27,"dddd") -> יום חמישי | C27: 297 | D27: 391 | F27: 12 | G27: 339 | H27: =D27-G27 -> 52 | I27: =H27/D27 -> 0.13299233
A28: =DATE(2024,9,1) + ROW(A27) - 1 -> 45562 | B28: =TEXT(A28,"dddd") -> יום שישי | C28: 0 | H28: =D28-G28 -> 0 | I28: 0
A29: =DATE(2024,9,1) + ROW(A28) - 1 -> 45563 | B29: =TEXT(A29,"dddd") -> שבת | C29: 0 | H29: =D29-G29 -> 0 | I29: 0
A30: =DATE(2024,9,1) + ROW(A29) - 1 -> 45564 | B30: =TEXT(A30,"dddd") -> יום ראשון | C30: 338 | D30: 561 | E30: נוכחות | F30: 15 | G30: 482 | H30: =D30-G30 -> 79 | I30: =H30/D30 -> 0.14081996
A31: =DATE(2024,9,1) + ROW(A30) - 1 -> 45565 | B31: =TEXT(A31,"dddd") -> יום שני | C31: 324 | D31: 535 | E31: נוכחות | F31: 14 | G31: 443 | H31: =D31-G31 -> 92 | I31: =H31/D31 -> 0.17196262
D32: =SUMPRODUCT(D2:D23,I2:I23)/SUM(D2:D23) -> 0.13114472

Sheet אוגוסט 25
A1: תאריך | B1: יום | C1: פניות כתובות נפתחו | D1: שיחות נכנסות | E1: הערות | F1: מספר נציגים | G1: שיחות ללא כפילויות | H1: מגמה פניות | I1: מגמה שיחות | J1: עזר | K1: אחוז | L1: נציגים צפויים | M1: מספר שעות | N1: כדי להגיע ליעד | O1: חיזוי קודם פניות | P1: חיזוי קודם שיחות | Q1: פער חיזוי פניות | R1: פער חיזוי שיחות
A2: =DATE(2025,8,1) + ROW(A1) - 1 -> 45870 | B2: =TEXT(A2,"dddd") -> יום שישי | C2: 0 | E2: חופש | H2: 0 | I2: 0 | J2: =D2-G2 -> 0 | K2: 0
A3: =DATE(2025,8,1) + ROW(A2) - 1 -> 45871 | B3: =TEXT(A3,"dddd") -> שבת | C3: 0 | E3: חופש | H3: 0 | I3: 0 | J3: =D3-G3 -> 0 | K3: 0
A4: =DATE(2025,8,1) + ROW(A3) - 1 -> 45872 | B4: =TEXT(A4,"dddd") -> יום ראשון | C4: 298 | D4: 632 | E4: ט באב | F4: 5 | G4: 416 | H4: 0 | I4: 0 | J4: =D4-G4 -> 216 | K4: =J4/D4 -> 0.34177215
A5: =DATE(2025,8,1) + ROW(A4) - 1 -> 45873 | B5: =TEXT(A5,"dddd") -> יום שני | C5: 222 | D5: 295 | F5: 7 | G5: 251 | H5: =(C5/'אוגוסט 24'!C5) - 1 -> 0.0090909091 | I5: =(G5/'אוגוסט 24'!G5) - 1 -> 0.096069869 | J5: =D5-G5 -> 44 | K5: =J5/D5 -> 0.14915254
A6: =DATE(2025,8,1) + ROW(A5) - 1 -> 45874 | B6: =TEXT(A6,"dddd") -> יום שלישי | C6: 205 | D6: 228 | F6: 10 | G6: 194 | H6: =(C6/'אוגוסט 24'!C6) - 1 -> 0.025 | I6: =(G6/'אוגוסט 24'!G6) - 1 -> -0.093457944 | J6: =D6-G6 -> 34 | K6: =J6/D6 -> 0.14912281
A7: =DATE(2025,8,1) + ROW(A6) - 1 -> 45875 | B7: =TEXT(A7,"dddd") -> יום רביעי | C7: 206 | D7: 187 | F7: 10 | G7: 157 | H7: =(C7/'אוגוסט 24'!C7) - 1 -> 0.22619048 | I7: =(G7/'אוגוסט 24'!G7) - 1 -> -0.11797753 | J7: =D7-G7 -> 30 | K7: =J7/D7 -> 0.16042781
A8: =DATE(2025,8,1) + ROW(A7) - 1 -> 45876 | B8: =TEXT(A8,"dddd") -> יום חמישי | C8: 198 | D8: 283 | F8: 12 | G8: 241 | H8: =(C8/'אוגוסט 24'!C8) - 1 -> -0.33557047 | I8: =(G8/'אוגוסט 24'!G8) - 1 -> -0.52277228 | J8: =D8-G8 -> 42 | K8: =J8/D8 -> 0.14840989
A9: =DATE(2025,8,1) + ROW(A8) - 1 -> 45877 | B9: =TEXT(A9,"dddd") -> יום שישי | C9: 0 | D9: 0 | E9: חופש | G9: 0 | H9: 0 | I9: 0 | J9: =D9-G9 -> 0 | K9: 0
A10: =DATE(2025,8,1) + ROW(A9) - 1 -> 45878 | B10: =TEXT(A10,"dddd") -> שבת | C10: 0 | D10: 0 | E10: חופש | G10: 0 | H10: 0 | I10: 0 | J10: =D10-G10 -> 0 | K10: 0
A11: =DATE(2025,8,1) + ROW(A10) - 1 -> 45879 | B11: =TEXT(A11,"dddd") -> יום ראשון | C11: 546 | D11: 738 | E11: תלוש | F11: 11 | G11: 559 | H11: 0 | I11: 0 | J11: =D11-G11 -> 179 | K11: =J11/D11 -> 0.24254743
A12: =DATE(2025,8,1) + ROW(A11) - 1 -> 45880 | B12: =TEXT(A12,"dddd") -> יום שני | C12: 334 | D12: 340 | E12: שכר | F12: 10 | G12: 289 | H12: =(C12/'אוגוסט 24'!C12) - 1 -> -0.020527859 | I12: =(G12/'אוגוסט 24'!G12) - 1 -> -0.033444816 | J12: =D12-G12 -> 51 | K12: =J12/D12 -> 0.15
A13: =DATE(2025,8,1) + ROW(A12) - 1 -> 45881 | B13: =TEXT(A13,"dddd") -> יום שלישי | C13: 264 | D13: 290 | E13: שכר | F13: 10 | G13: 248 | H13: =(C13/'אוגוסט 24'!C13) - 1 -> -0.0037735849 | I13: =(G13/'אוגוסט 24'!G13) - 1 -> -0.35416667 | J13: =D13-G13 -> 42 | K13: =J13/D13 -> 0.14482759
A14: =DATE(2025,8,1) + ROW(A13) - 1 -> 45882 | B14: =TEXT(A14,"dddd") -> יום רביעי | C14: 277 | D14: 431 | E14: שכר | F14: 10 | G14: 370 | H14: =(C14/'אוגוסט 24'!C14) - 1 -> 0.29439252 | I14: =(G14/'אוגוסט 24'!G14) - 1 -> 0.86868687 | J14: =D14-G14 -> 61 | K14: =J14/D14 -> 0.14153132
A15: =DATE(2025,8,1) + ROW(A14) - 1 -> 45883 | B15: =TEXT(A15,"dddd") -> יום חמישי | C15: 244 | D15: 248 | F15: 9 | G15: 209 | H15: =(C15/'אוגוסט 24'!C15) - 1 -> -0.0081300813 | I15: =(G15/'אוגוסט 24'!G15) - 1 -> -0.066964286 | J15: =D15-G15 -> 39 | K15: =J15/D15 -> 0.15725806
A16: =DATE(2025,8,1) + ROW(A15) - 1 -> 45884 | B16: =TEXT(A16,"dddd") -> יום שישי | C16: 0 | D16: 0 | E16: חופש | G16: 0 | H16: 0 | I16: 0 | J16: =D16-G16 -> 0 | K16: 0
A17: =DATE(2025,8,1) + ROW(A16) - 1 -> 45885 | B17: =TEXT(A17,"dddd") -> שבת | C17: 0 | D17: 0 | E17: חופש | G17: 0 | H17: 0 | I17: 0 | J17: =D17-G17 -> 0 | K17: 0
A18: =DATE(2025,8,1) + ROW(A17) - 1 -> 45886 | B18: =TEXT(A18,"dddd") -> יום ראשון | C18: 259 | D18: 275 | G18: 244 | H18: =(C18/'אוגוסט 24'!C19) - 1 -> -0.32552083 | I18: =(G18/'אוגוסט 24'!G19) - 1 -> -0.17845118 | J18: =D18-G18 -> 31 | K18: =J18/D18 -> 0.11272727
A19: =DATE(2025,8,1) + ROW(A18) - 1 -> 45887 | B19: =TEXT(A19,"dddd") -> יום שני | C19: 428 | D19: 307 | G19: 272 | H19: =(C19/'אוגוסט 24'!C20) - 1 -> 0.38511327 | I19: =(G19/'אוגוסט 24'!G20) - 1 -> 0.1147541 | J19: =D19-G19 -> 35 | K19: =J19/D19 -> 0.11400651
A20: =DATE(2025,8,1) + ROW(A19) - 1 -> 45888 | B20: =TEXT(A20,"dddd") -> יום שלישי | C20: 334 | D20: 290 | F20: 10 | G20: 242 | H20: =(C20/'אוגוסט 24'!C21) - 1 -> 0.18439716 | I20: =(G20/'אוגוסט 24'!G21) - 1 -> -0.14487633 | J20: =D20-G20 -> 48 | K20: =J20/D20 -> 0.16551724 | O20: 328.74816 | P20: 340.2211
A21: =DATE(2025,8,1) + ROW(A20) - 1 -> 45889 | B21: =TEXT(A21,"dddd") -> יום רביעי | C21: 239 | D21: 229 | F21: 9 | G21: 202 | H21: =(C21/'אוגוסט 24'!C22) - 1 -> -0.29080119 | I21: =(G21/'אוגוסט 24'!G22) - 1 -> -0.24907063 | J21: =D21-G21 -> 27 | K21: =J21/D21 -> 0.11790393 | L21: 8 | M21: =8*L21 -> 64 | N21: =(D21+C21)/8 -> 58.5 | O21: 393 | P21: 323
A22: =DATE(2025,8,1) + ROW(A21) - 1 -> 45890 | B22: =TEXT(A22,"dddd") -> יום חמישי | C22: 261 | D22: 272 | F22: 8 | G22: 234 | H22: =(C22/'אוגוסט 24'!C23) - 1 -> -0.040441176 | I22: =(G22/'אוגוסט 24'!G23) - 1 -> -0.38421053 | J22: =D22-G22 -> 38 | K22: =J22/D22 -> 0.13970588 | L22: 8 | M22: =8*L22 -> 64 | N22: =(D22+C22)/8 -> 66.625 | O22: 317 | P22: 457
A23: =DATE(2025,8,1) + ROW(A22) - 1 -> 45891 | B23: =TEXT(A23,"dddd") -> יום שישי | C23: 0 | D23: 0 | E23: חופש | G23: 0 | H23: 0 | I23: 0 | J23: =D23-G23 -> 0 | K23: 0 | L23: 0 | M23: =8*L23 -> 0 | N23: =(D23+C23)/8 -> 0
A24: =DATE(2025,8,1) + ROW(A23) - 1 -> 45892 | B24: =TEXT(A24,"dddd") -> שבת | C24: 0 | D24: 0 | E24: חופש | G24: 0 | H24: 0 | I24: 0 | J24: =D24-G24 -> 0 | K24: 0 | L24: 0 | M24: =8*L24 -> 0 | N24: =(D24+C24)/8 -> 0
A25: =DATE(2025,8,1) + ROW(A24) - 1 -> 45893 | B25: =TEXT(A25,"dddd") -> יום ראשון | C25: 280 | D25: 276 | G25: 238 | H25: =(C25/'אוגוסט 24'!C26) - 1 -> 0.048689139 | I25: =(G25/'אוגוסט 24'!G26) - 1 -> -0.27217125 | J25: =D25-G25 -> 38 | K25: =J25/D25 -> 0.13768116 | L25: 8 | M25: =8*L25 -> 64 | N25: =(D25+C25)/8 -> 69.5
A26: =DATE(2025,8,1) + ROW(A25) - 1 -> 45894 | B26: =TEXT(A26,"dddd") -> יום שני | C26: ='אוגוסט 24'!C27 * (1 + $H$33) -> 256.94026 | D26: ='אוגוסט 24'!G27 * (1 + $I$33)*(1+0.167) -> 305.58131 | L26: 8 | M26: =8*L26 -> 64 | N26: =(D26+C26)/8 -> 70.315197
A27: =DATE(2025,8,1) + ROW(A26) - 1 -> 45895 | B27: =TEXT(A27,"dddd") -> יום שלישי | C27: ='אוגוסט 24'!C28 * (1 + $H$33) -> 223.91983 | D27: ='אוגוסט 24'!G28 * (1 + $I$33)*(1+0.167) -> 278.27851 | L27: 8 | M27: =8*L27 -> 64 | N27: =(D27+C27)/8 -> 62.774792
A28: =DATE(2025,8,1) + ROW(A27) - 1 -> 45896 | B28: =TEXT(A28,"dddd") -> יום רביעי | C28: ='אוגוסט 24'!C29 * (1 + $H$33) -> 214.63283 | D28: ='אוגוסט 24'!G29 * (1 + $I$33)*(1+0.167) -> 342.33507 | L28: 8 | M28: =8*L28 -> 64 | N28: =(D28+C28)/8 -> 69.620988
A29: =DATE(2025,8,1) + ROW(A28) - 1 -> 45897 | B29: =TEXT(A29,"dddd") -> יום חמישי | C29: ='אוגוסט 24'!C30 * (1 + $H$33) -> 208.4415 | D29: ='אוגוסט 24'!G30 * (1 + $I$33)*(1+0.167) -> 287.72948 | E29: נוכחות | L29: 8 | M29: =8*L29 -> 64 | N29: =(D29+C29)/8 -> 62.021372
A30: =DATE(2025,8,1) + ROW(A29) - 1 -> 45898 | B30: =TEXT(A30,"dddd") -> יום שישי | C30: ='אוגוסט 24'!C31 * (1 + $H$33) -> 0 | D30: ='אוגוסט 24'!G31 * (1 + $I$33)*(1+0.167) -> 0 | E30: חופש | G30: 0 | L30: 0 | M30: =8*L30 -> 0 | N30: =(D30+C30)/8 -> 0
A31: =DATE(2025,8,1) + ROW(A30) - 1 -> 45899 | B31: =TEXT(A31,"dddd") -> שבת | C31: ='אוגוסט 24'!C32 * (1 + $H$33) -> 0 | D31: ='אוגוסט 24'!G32 * (1 + $I$33)*(1+0.167) -> 0 | E31: חופש | G31: 0 | L31: 0 | M31: =8*L31 -> 0 | N31: =(D31+C31)/8 -> 0
A32: =DATE(2025,8,1) + ROW(A31) - 1 -> 45900 | B32: =TEXT(A32,"dddd") -> יום ראשון | C32: ='אוגוסט 24'!C12 * (1 + $H$33) -> 351.87402 | D32: ='אוגוסט 24'!G12 * (1 + $I$33)*(1+0.167) -> 313.98217 | E32: נוכחות | L32: 8 | M32: =8*L32 -> 64 | N32: =(D32+C32)/8 -> 83.232023
H33: =SUM(C2:C25)/SUM('אוגוסט 24'!C2:C26) - 1 -> 0.031888614 | I33: =SUM(G2:G25)/SUM('אוגוסט 24'!G2:G26) - 1 -> -0.10016488 | J33: =SUMPRODUCT(D2:D25,K2:K25)/SUM(D2:D25) -> 0.17947754

Sheet ספטמבר 25
A1: תאריך | B1: יום | C1: פניות כתובות נפתחו | D1: שיחות נכנסות | E1: הערות | F1: מספר נציגים | G1: שיחות ללא כפילויות | H1: נציגים צפויים | I1: מספר שעות | J1: כדי להגיע ליעד
